Workbook

Sheet ISM Manu
Z1: https://etfdb.com/etf/XLV/#etf-holdings&sort_name=weight&sort_order=desc&page=1 | AD1: https://money.usnews.com/investing/stocks/metal-fabrication
B2: WIKIPEDIA | C2: 3 | Z2: https://www.nasdaq.com/markets/barchart-sectors.aspx | AD2: https://etfdb.com/etfs/ | AF2: https://etfdb.com/etfs/
B3: Yahoo Finance Screener | C3: 6 | Z3: https://www.barchart.com/stocks/sectors/rankings | AF3: https://www.instituteforsupplymanagement.org/news/content.cfm?ItemNumber=28859
B4: Link(s) | C4: Past __ Mnths | D4: ( + ) Count | E4: Link | F4: Link | G4: Link | H4: Link | I4: Link | J4: Link | K4: Link | L4: Link | M4: Link | N4: Link | O4: Link | P4: Link | Q4: Link | R4: Link | S4: Link | T4: Link | Z4: https://www.macrotrends.net/stocks/sector/2/consumer-discretionary | BO4: =MAX(BO7:BO24) -> 8 | BP4: =MAX(BP7:BP24) -> 5 | BQ4: =MAX(BQ7:BQ24) -> 5 | BR4: =MAX(BR7:BR24) -> 5 | BS4: =MAX(BS7:BS24) -> 5 | BT4: =MAX(BT7:BT24) -> 3 | BU4: =MAX(BU7:BU24) -> 7 | BV4: =MAX(BV7:BV24) -> 8 | ... CD4: =MAX(CD7:CD24) -> 5
B5: Sectors | C5: 3 | E5: 43556 | F5: 43586 | G5: 43617 | H5: 43647 | I5: 43678 | J5: 43709 | K5: 43739 | L5: 43770 | M5: 43800 | N5: 43831 | O5: 43862 | P5: 43891 | Q5: 43922 | R5: 43952 | S5: 43983 | T5: 44013 | U5: 44044 | V5: 44075 | W5: 44105 | X5: 44136 | Y5: 44166 | Z5: 44197 | AA5: 44228 | AB5: 44256 | AC5: 44287 | AD5: 44317 | AE5: 44348 | AF5: 44378 | AG5: 44409 | AH5: 44440 | AI5: 44470 | AJ5: 44501 | AK5: 44531 | AL5: 44562 | AM5: 44593 | AN5: 44621 | AO5: 44652 | AP5: 44682 | AQ5: 44713 | AR5: 44743 | AS5: 44774 | AT5: 44805 | AU5: 44835 | AV5: 44866 | AW5: 44896 | AX5: 44927 | AY5: 44958 | AZ5: 44986 | BA5: 45017 | BB5: 45047 | BC5: 45078 | BD5: 45108 | BE5: 45139 | BF5: 45170 | BG5: 45200 | BH5: 45231 | BI5: 45261 | BJ5: 45292 | BK5: 45323 | BL5: 45352 | BM5: 45383 | BN5: 45413 | BO5: 45444 | BP5: 45474 | BQ5: 45505 | BR5: 45536 | BS5: 45566 | BT5: 45597 | BU5: 45627 | BV5: 45658 | BW5: 45689 | BX5: 45717 | BY5: 45748 | BZ5: 45778 | CA5: 45809 | CB5: 45839 | CC5: 45870 | CD5: 45901 | CE5: 45931
A6: AVERAGE | E6: =AVERAGE(E7:E24) -> 4.5555556 | F6: =AVERAGE(F7:F24) -> 2.6111111 | G6: =AVERAGE(G7:G24) -> 3.5 | H6: =AVERAGE(H7:H24) -> 0 | I6: =AVERAGE(I7:I24) -> 0.94444444 | J6: =AVERAGE(J7:J24) -> -6.3333333 | K6: =AVERAGE(K7:K24) -> -3.5 | L6: =AVERAGE(L7:L24) -> -4.2222222 | ... CE6: =AVERAGE(CE7:CE24) -> -3.1666667
A7: PMI Itself | B7: Apparel, Leather & Allied Products | D7: =IF(COUNTIF(S7:X7,">0")=0,(COUNTIF(S7:X7,"<0")*-1),COUNTIF(S7:X7,">0")) -> 5 | E7: -5 | F7: -6 | G7: -5 | H7: -9 | I7: -7 | J7: -15 | K7: -11 | L7: 5 | M7: 0 | N7: -7 | O7: 0 | P7: 8 | Q7: 0 | R7: 4 | S7: 9 | T7: 6 | U7: 6 | V7: -4 | W7: 15 | X7: 16 | Y7: 16 | Z7: 9 | AA7: 5 | AB7: 13 | AC7: 6 | AD7: 0 | AE7: 0 | AF7: 15 | AG7: 0 | AH7: 11 | AI7: 16 | AJ7: 13 | AK7: 15 | AL7: 14 | AM7: 16 | AN7: 15 | AO7: 17 | AP7: 15 | AQ7: 15 | AR7: 11 | AS7: -6 | AT7: 5 | AU7: 8 | AV7: 6 | AW7: -6 | AX7: -11 | AY7: 4 | AZ7: -5 | BA7: 4 | BB7: -12 | BC7: 0 | BD7: -16 | BE7: -13 | BF7: 0 | BG7: 0 | BH7: -10 | BI7: -15 | BJ7: 4 | BK7: 8 | BL7: 0 | BM7: 0 | BN7: 0 | BO7: 0 | BP7: 0 | BQ7: 0 | BR7: -10 | BS7: 5 | BT7: 0 | BU7: 0 | BV7: 0 | BW7: 0 | BX7: 0 | BY7: 11 | BZ7: 0 | CA7: 9 | CB7: 7 | CC7: 6 | CD7: -10 | CE7: -11
B8: Chemical Products | D8: =IF(COUNTIF(S8:X8,">0")=0,(COUNTIF(S8:X8,"<0")*-1),COUNTIF(S8:X8,">0")) -> 6 | E8: 9 | F8: 4 | G8: 6 | H8: 1 | I8: 1 | J8: 1 | K8: -6 | L8: -2 | M8: -2 | N8: 2 | O8: 1 | P8: 5 | Q8: -1 | R8: -3 | S8: 5 | T8: 7 | U8: 11 | V8: 7 | W8: 6 | X8: 8 | Y8: 7 | Z8: 13 | AA8: 12 | AB8: 5 | AC8: 11 | AD8: 6 | AE8: 12 | AF8: 8 | AG8: 8 | AH8: 12 | AI8: 8 | AJ8: 4 | AK8: 8 | AL8: 3 | AM8: 2 | AN8: 5 | AO8: 5 | AP8: 4 | AQ8: 1 | AR8: -1 | AS8: -3 | AT8: -2 | AU8: -4 | AV8: -6 | AW8: -11 | AX8: -5 | AY8: -6 | AZ8: -4 | BA8: -6 | BB8: -7 | BC8: -8 | BD8: -10 | BE8: -6 | BF8: -2 | BG8: -2 | BH8: -4 | BI8: -1 | BJ8: 1 | BK8: 3 | BL8: 2 | BM8: 2 | BN8: 1 | BO8: 3 | BP8: -2 | BQ8: -2 | BR8: -3 | BS8: -8 | BT8: -9 | BU8: -3 | BV8: 5 | BW8: 4 | BX8: -3 | BY8: 2 | BZ8: -2 | CA8: -3 | CB8: -8 | CC8: -2 | CD8: -6 | CE8: -4
B9: Computer & Electronic Products | D9: =IF(COUNTIF(S9:X9,">0")=0,(COUNTIF(S9:X9,"<0")*-1),COUNTIF(S9:X9,">0")) -> 6 | E9: 3 | F9: 5 | G9: 5 | H9: 4 | I9: 0 | J9: -1 | K9: 1 | L9: 1 | M9: -3 | N9: 5 | O9: 6 | P9: 4 | Q9: -3 | R9: -2 | S9: 7 | T9: 5 | U9: 10 | V9: 2 | W9: 4 | X9: 6 | Y9: 11 | Z9: 1 | AA9: 6 | AB9: 14 | AC9: 8 | AD9: 11 | AE9: 14 | AF9: 13 | AG9: 14 | AH9: 13 | AI9: 9 | AJ9: 10 | AK9: 5 | AL9: 4 | AM9: 8 | AN9: 4 | AO9: 13 | AP9: 11 | AQ9: 12 | AR9: 7 | AS9: 7 | AT9: 2 | AU9: -2 | AV9: -4 | AW9: -5 | AX9: -1 | AY9: -4 | AZ9: -3 | BA9: -3 | BB9: -5 | BC9: -5 | BD9: -11 | BE9: -5 | BF9: -5 | BG9: -7 | BH9: -11 | BI9: -6 | BJ9: -8 | BK9: -4 | BL9: -2 | BM9: 0 | BN9: -4 | BO9: -1 | BP9: -1 | BQ9: 1 | BR9: -1 | BS9: 2 | BT9: 2 | BU9: 0 | BV9: -3 | BW9: -2 | BX9: 5 | BY9: 6 | BZ9: 0 | CA9: 4 | CB9: -4 | CC9: -3 | CD9: -1 | CE9: -1
B10: Electrical Equipment, Appliances & Components | D10: =IF(COUNTIF(S10:X10,">0")=0,(COUNTIF(S10:X10,"<0")*-1),COUNTIF(S10:X10,">0")) -> 6 | E10: 12 | F10: 6 | G10: 2 | H10: -2 | I10: -1 | J10: -12 | K10: -4 | L10: -1 | M10: -6 | N10: -6 | O10: 4 | P10: 0 | Q10: -7 | R10: -4 | S10: 1 | T10: 1 | U10: 3 | V10: 10 | W10: 2 | X10: 12 | Y10: 3 | Z10: 16 | AA10: 15 | AB10: 16 | AC10: 18 | AD10: 10 | AE10: 15 | AF10: 3 | AG10: 11 | AH10: 14 | AI10: 13 | AJ10: 11 | AK10: 7 | AL10: 9 | AM10: 9 | AN10: 12 | AO10: 9 | AP10: 1 | AQ10: 10 | AR10: 1 | AS10: -1 | AT10: 1 | AU10: 1 | AV10: -1 | AW10: -8 | AX10: -9 | AY10: 1 | AZ10: -2 | BA10: -8 | BB10: -4 | BC10: -6 | BD10: -7 | BE10: -7 | BF10: -3 | BG10: -11 | BH10: -12 | BI10: -3 | BJ10: -4 | BK10: -1 | BL10: -4 | BM10: 5 | BN10: 0 | BO10: -2 | BP10: -8 | BQ10: -8 | BR10: -6 | BS10: -7 | BT10: 1 | BU10: 6 | BV10: 1 | BW10: 5 | BX10: 2 | BY10: 8 | BZ10: 3 | CA10: 1 | CB10: -2 | CC10: -4 | CD10: -5 | CE10: -5
B11: Fabricated Metal Products | D11: =IF(COUNTIF(S11:X11,">0")=0,(COUNTIF(S11:X11,"<0")*-1),COUNTIF(S11:X11,">0")) -> 4 | E11: 1 | F11: -1 | G11: -1 | H11: -8 | I11: -6 | J11: -9 | K11: -3 | L11: -9 | M11: -7 | N11: 1 | O11: 3 | P11: -2 | Q11: -11 | R11: -7 | S11: -2 | T11: -1 | U11: 8 | V11: 8 | W11: 14 | X11: 11 | Y11: 13 | Z11: 12 | AA11: 10 | AB11: 11 | AC11: 14 | AD11: 9 | AE11: 11 | AF11: 10 | AG11: 10 | AH11: 5 | AI11: 7 | AJ11: 2 | AK11: 6 | AL11: 5 | AM11: 5 | AN11: 7 | AO11: 3 | AP11: 5 | AQ11: 5 | AR11: -3 | AS11: -2 | AT11: -1 | AU11: -5 | AV11: -8 | AW11: -12 | AX11: -6 | AY11: -3 | AZ11: 4 | BA11: 2 | BB11: 1 | BC11: -3 | BD11: -4 | BE11: -9 | BF11: -7 | BG11: -9 | BH11: -3 | BI11: -7 | BJ11: -7 | BK11: 4 | BL11: 3 | BM11: -2 | BN11: 2 | BO11: -7 | BP11: -6 | BQ11: -7 | BR11: -2 | BS11: -2 | BT11: -6 | BU11: -6 | BV11: -5 | BW11: 2 | BX11: 7 | BY11: -1 | BZ11: 2 | CA11: -1 | CB11: -5 | CC11: -1 | CD11: 2 | CE11: 2
B12: Food, Beverage & Tobacco Products | D12: =IF(COUNTIF(S12:X12,">0")=0,(COUNTIF(S12:X12,"<0")*-1),COUNTIF(S12:X12,">0")) -> 6 | E12: 4 | F12: 3 | G12: 8 | H12: 6 | I12: 7 | J12: 2 | K12: 3 | L12: 4 | M12: 2 | N12: 6 | O12: 7 | P12: 9 | Q12: 1 | R12: 3 | S12: 8 | T12: 9 | U12: 13 | V12: 12 | W12: 12 | X12: 1 | Y12: 2 | Z12: 6 | AA12: 4 | AB12: 10 | AC12: 9 | AD12: 8 | AE12: 5 | AF12: 7 | AG12: 6 | AH12: 6 | AI12: 10 | AJ12: 6 | AK12: 4 | AL12: 8 | AM12: 4 | AN12: 13 | AO12: 12 | AP12: 10 | AQ12: 2 | AR12: -2 | AS12: 1 | AT12: 3 | AU12: -1 | AV12: -3 | AW12: -3 | AX12: -3 | AY12: -7 | AZ12: -6 | BA12: -2 | BB12: -6 | BC12: -2 | BD12: -8 | BE12: 3 | BF12: 4 | BG12: 2 | BH12: 3 | BI12: 0 | BJ12: -5 | BK12: -3 | BL12: 4 | BM12: -3 | BN12: -1 | BO12: -3 | BP12: -5 | BQ12: 2 | BR12: 4 | BS12: 4 | BT12: 3 | BU12: 0 | BV12: -1 | BW12: 6 | BX12: -2 | BY12: -3 | BZ12: -4 | CA12: 2 | CB12: -1 | CC12: 4 | CD12: 0 | CE12: 5
B13: Furniture & Related Products | D13: =IF(COUNTIF(S13:X13,">0")=0,(COUNTIF(S13:X13,"<0")*-1),COUNTIF(S13:X13,">0")) -> 5 | E13: 5 | F13: 10 | G13: 12 | H13: 7 | I13: 8 | J13: -2 | K13: 5 | L13: -11 | M13: -11 | N13: 8 | O13: 13 | P13: -3 | Q13: -14 | R13: 5 | S13: 11 | T13: 12 | U13: -1 | V13: 11 | W13: 9 | X13: 2 | Y13: 15 | Z13: 4 | AA13: 2 | AB13: 12 | AC13: 16 | AD13: 16 | AE13: 17 | AF13: 17 | AG13: 15 | AH13: 17 | AI13: 15 | AJ13: 12 | AK13: 14 | AL13: 13 | AM13: 7 | AN13: 14 | AO13: 6 | AP13: -1 | AQ13: -1 | AR13: -6 | AS13: -5 | AT13: -7 | AU13: -10 | AV13: -7 | AW13: -7 | AX13: -12 | AY13: -10 | AZ13: -12 | BA13: -11 | BB13: 3 | BC13: 0 | BD13: 1 | BE13: -12 | BF13: -10 | BG13: -6 | BH13: -6 | BI13: -4 | BJ13: -9 | BK13: -7 | BL13: -6 | BM13: -5 | BN13: -3 | BO13: 5 | BP13: 2 | BQ13: 3 | BR13: 2 | BS13: 0 | BT13: -5 | BU13: 4 | BV13: -4 | BW13: -5 | BX13: -4 | BY13: -5 | BZ13: 4 | CA13: 5 | CB13: 2 | CC13: -6 | CD13: -7 | CE13: -10
B14: Machinery | D14: =IF(COUNTIF(S14:X14,">0")=0,(COUNTIF(S14:X14,"<0")*-1),COUNTIF(S14:X14,">0")) -> 4 | E14: 6 | F14: 1 | G14: 1 | H14: -1 | I14: 3 | J14: -3 | K14: -7 | L14: -3 | M14: -1 | N14: -1 | O14: 2 | P14: -1 | Q14: -9 | R14: -6 | S14: -1 | T14: -2 | U14: 7 | V14: 4 | W14: 10 | X14: 7 | Y14: 12 | Z14: 15 | AA14: 11 | AB14: 15 | AC14: 15 | AD14: 7 | AE14: 16 | AF14: 11 | AG14: 13 | AH14: 15 | AI14: 12 | AJ14: 9 | AK14: 11 | AL14: 10 | AM14: 12 | AN14: 10 | AO14: 16 | AP14: 13 | AQ14: 11 | AR14: 5 | AS14: 3 | AT14: 8 | AU14: 6 | AV14: -2 | AW14: -4 | AX14: -4 | AY14: -2 | AZ14: 1 | BA14: -5 | BB14: -2 | BC14: -1 | BD14: -1 | BE14: -1 | BF14: -4 | BG14: -10 | BH14: -8 | BI14: -13 | BJ14: -12 | BK14: -6 | BL14: -3 | BM14: -6 | BN14: -5 | BO14: -8 | BP14: -9 | BQ14: -4 | BR14: -4 | BS14: -6 | BT14: -4 | BU14: -4 | BV14: 4 | BW14: -1 | BX14: -1 | BY14: 3 | BZ14: 1 | CA14: 3 | CB14: -7 | CC14: -5 | CD14: -2 | CE14: -3
B15: Miscellaneous Manufacturing | D15: =IF(COUNTIF(S15:X15,">0")=0,(COUNTIF(S15:X15,"<0")*-1),COUNTIF(S15:X15,">0")) -> 6 | E15: 11 | F15: 7 | G15: 3 | H15: -3 | I15: 2 | J15: 3 | K15: -2 | L15: 2 | M15: 1 | N15: 4 | O15: 5 | P15: 2 | Q15: -4 | R15: -5 | S15: 4 | T15: 2 | U15: 4 | V15: 6 | W15: 1 | X15: 4 | Y15: 1 | Z15: 3 | AA15: 3 | AB15: 3 | AC15: 12 | AD15: 5 | AE15: 9 | AF15: 14 | AG15: 7 | AH15: 7 | AI15: 6 | AJ15: 5 | AK15: 9 | AL15: 12 | AM15: 11 | AN15: 11 | AO15: 2 | AP15: 3 | AQ15: 4 | AR15: -4 | AS15: 2 | AT15: 6 | AU15: 3 | AV15: 3 | AW15: -1 | AX15: 2 | AY15: -1 | AZ15: 5 | BA15: -1 | BB15: -1 | BC15: -7 | BD15: -5 | BE15: 1 | BF15: 0 | BG15: -4 | BH15: -5 | BI15: -5 | BJ15: -2 | BK15: 2 | BL15: -1 | BM15: -7 | BN15: 0 | BO15: 2 | BP15: 3 | BQ15: -1 | BR15: 1 | BS15: 1 | BT15: -2 | BU15: 2 | BV15: -7 | BW15: 9 | BX15: 1 | BY15: 4 | BZ15: 0 | CA15: 6 | CB15: 3 | CC15: 2 | CD15: 1 | CE15: -2
B16: Nonmetallic Mineral Products | D16: =IF(COUNTIF(S16:X16,">0")=0,(COUNTIF(S16:X16,"<0")*-1),COUNTIF(S16:X16,">0")) -> 5 | E16: 8 | F16: 2 | G16: 9 | H16: -6 | I16: 4 | J16: -4 | K16: 0 | L16: -4 | M16: -10 | N16: 3 | O16: -1 | P16: 0 | Q16: -10 | R16: 6 | S16: 3 | T16: 0 | U16: 5 | V16: 9 | W16: 13 | X16: 15 | Y16: -1 | Z16: 5 | AA16: 1 | AB16: 4 | AC16: 7 | AD16: 15 | AE16: 8 | AF16: 12 | AG16: -1 | AH16: 2 | AI16: -1 | AJ16: 0 | AK16: 10 | AL16: 11 | AM16: 3 | AN16: 3 | AO16: 14 | AP16: 12 | AQ16: 8 | AR16: 10 | AS16: 10 | AT16: 9 | AU16: 7 | AV16: 5 | AW16: 0 | AX16: -7 | AY16: -9 | AZ16: -11 | BA16: -9 | BB16: 4 | BC16: 3 | BD16: -2 | BE16: -2 | BF16: 5 | BG16: 0 | BH16: 2 | BI16: -12 | BJ16: -10 | BK16: 7 | BL16: 8 | BM16: 9 | BN16: 0 | BO16: 1 | BP16: 1 | BQ16: -10 | BR16: -7 | BS16: -4 | BT16: -3 | BU16: -1 | BV16: -8 | BW16: -3 | BX16: 4 | BY16: 5 | BZ16: 6 | CA16: 7 | CB16: 5 | CC16: 5 | CD16: -3 | CE16: 1
B17: Paper Products | D17: =IF(COUNTIF(S17:X17,">0")=0,(COUNTIF(S17:X17,"<0")*-1),COUNTIF(S17:X17,">0")) -> 5 | E17: 8 | F17: -2 | G17: 4 | H17: -4 | I17: -2 | J17: -10 | K17: -1 | L17: 3 | M17: -5 | N17: 0 | O17: 10 | P17: 6 | Q17: 2 | R17: 2 | S17: 2 | T17: 0 | U17: 2 | V17: 14 | W17: 8 | X17: 5 | Y17: 8 | Z17: 8 | AA17: 13 | AB17: 7 | AC17: 4 | AD17: 2 | AE17: 4 | AF17: 9 | AG17: 2 | AH17: 9 | AI17: 3 | AJ17: 7 | AK17: -1 | AL17: -1 | AM17: 14 | AN17: 6 | AO17: 8 | AP17: 8 | AQ17: -3 | AR17: -5 | AS17: -4 | AT17: -3 | AU17: -8 | AV17: -10 | AW17: -10 | AX17: -13 | AY17: -13 | AZ17: -8 | BA17: 0 | BB17: -10 | BC17: -4 | BD17: -14 | BE17: -4 | BF17: -8 | BG17: -5 | BH17: -14 | BI17: -9 | BJ17: -3 | BK17: -2 | BL17: 7 | BM17: -1 | BN17: 5 | BO17: 4 | BP17: -3 | BQ17: -3 | BR17: -5 | BS17: -1 | BT17: -8 | BU17: 3 | BV17: -2 | BW17: 0 | BX17: -6 | BY17: -4 | BZ17: -7 | CA17: -4 | CB17: -9 | CC17: -10 | CD17: -8 | CE17: -9
B18: Petroleum & Coal Products | D18: =IF(COUNTIF(S18:X18,">0")=0,(COUNTIF(S18:X18,"<0")*-1),COUNTIF(S18:X18,">0")) -> 1 | E18: -2 | F18: -4 | G18: 7 | H18: 2 | I18: 5 | J18: -7 | K18: -5 | L18: -5 | M18: 0 | N18: -5 | O18: -3 | P18: -6 | Q18: -6 | R18: -8 | S18: 0 | T18: 3 | U18: -2 | V18: -2 | W18: 0 | X18: -1 | Y18: 6 | Z18: -1 | AA18: -1 | AB18: 1 | AC18: 3 | AD18: 1 | AE18: 1 | AF18: 1 | AG18: 1 | AH18: 16 | AI18: 5 | AJ18: 3 | AK18: 1 | AL18: 2 | AM18: 1 | AN18: -1 | AO18: -1 | AP18: 7 | AQ18: 3 | AR18: 9 | AS18: 9 | AT18: 0 | AU18: 5 | AV18: 2 | AW18: 1 | AX18: -2 | AY18: 2 | AZ18: 3 | BA18: 3 | BB18: -8 | BC18: 0 | BD18: 2 | BE18: 2 | BF18: 1 | BG18: 0 | BH18: 0 | BI18: -10 | BJ18: -6 | BK18: 0 | BL18: 6 | BM18: 4 | BN18: 6 | BO18: 7 | BP18: 4 | BQ18: 4 | BR18: 5 | BS18: 3 | BT18: 0 | BU18: 0 | BV18: 6 | BW18: 10 | BX18: 8 | BY18: 10 | BZ18: 5 | CA18: 8 | CB18: 0 | CC18: 3 | CD18: 5 | CE18: -6
B19: Plastics & Rubber Products | D19: =IF(COUNTIF(S19:X19,">0")=0,(COUNTIF(S19:X19,"<0")*-1),COUNTIF(S19:X19,">0")) -> 6 | E19: 7 | F19: 9 | G19: 0 | H19: 5 | I19: -3 | J19: =+-8 -> -8 | K19: -8 | L19: -6 | M19: 0 | N19: 0 | O19: 12 | P19: 1 | Q19: -8 | R19: -1 | S19: 6 | T19: 8 | U19: 14 | V19: 5 | W19: 11 | X19: 10 | Y19: 9 | Z19: 11 | AA19: 7 | AB19: 8 | AC19: 10 | AD19: 14 | AE19: 13 | AF19: 5 | AG19: 9 | AH19: 1 | AI19: 4 | AJ19: 8 | AK19: 12 | AL19: 1 | AM19: 6 | AN19: 1 | AO19: 15 | AP19: 6 | AQ19: 7 | AR19: 2 | AS19: 5 | AT19: 7 | AU19: 2 | AV19: -5 | AW19: -9 | AX19: -10 | AY19: -8 | AZ19: -9 | BA19: -7 | BB19: -3 | BC19: -11 | BD19: -15 | BE19: -11 | BF19: -9 | BG19: 1 | BH19: -1 | BI19: -14 | BJ19: -11 | BK19: 5 | BL19: -5 | BM19: 1 | BN19: -6 | BO19: -4 | BP19: -10 | BQ19: -9 | BR19: -12 | BS19: -3 | BT19: -10 | BU19: 1 | BV19: 2 | BW19: 3 | BX19: -5 | BY19: 9 | BZ19: 7 | CA19: 0 | CB19: 6 | CC19: -8 | CD19: -9 | CE19: 3
B20: Primary Metals | D20: =IF(COUNTIF(S20:X20,">0")=0,(COUNTIF(S20:X20,"<0")*-1),COUNTIF(S20:X20,">0")) -> 4 | E20: -4 | F20: -5 | G20: -4 | H20: -7 | I20: -4 | J20: -6 | K20: -12 | L20: -7 | M20: -4 | N20: -2 | O20: 8 | P20: 3 | Q20: -2 | R20: -10 | S20: -3 | T20: 4 | U20: 9 | V20: -1 | W20: 5 | X20: 9 | Y20: 5 | Z20: 14 | AA20: 14 | AB20: 9 | AC20: 13 | AD20: 12 | AE20: 6 | AF20: 6 | AG20: 12 | AH20: 3 | AI20: 2 | AJ20: -1 | AK20: 2 | AL20: 6 | AM20: 10 | AN20: 2 | AO20: 7 | AP20: 2 | AQ20: 9 | AR20: 3 | AS20: 4 | AT20: 0 | AU20: -3 | AV20: 4 | AW20: 2 | AX20: -8 | AY20: -5 | AZ20: 2 | BA20: -4 | BB20: -13 | BC20: 2 | BD20: -9 | BE20: -10 | BF20: 2 | BG20: -3 | BH20: -7 | BI20: 1 | BJ20: -1 | BK20: 6 | BL20: 5 | BM20: 7 | BN20: 3 | BO20: 6 | BP20: -11 | BQ20: 5 | BR20: -9 | BS20: -5 | BT20: -1 | BU20: 7 | BV20: 7 | BW20: 8 | BX20: 6 | BY20: 1 | BZ20: -1 | CA20: 0 | CB20: 1 | CC20: 1 | CD20: 4 | CE20: 6
B21: Printing & Related Support Activities | D21: =IF(COUNTIF(S21:X21,">0")=0,(COUNTIF(S21:X21,"<0")*-1),COUNTIF(S21:X21,">0")) -> 2 | E21: 10 | F21: 11 | G21: 11 | H21: 8 | I21: 0 | J21: -14 | K21: 4 | L21: -12 | M21: -9 | N21: -8 | O21: 11 | P21: 10 | Q21: -15 | R21: -11 | S21: 10 | T21: 10 | U21: -3 | V21: -3 | W21: -1 | X21: -2 | Y21: -2 | Z21: -2 | AA21: -2 | AB21: 2 | AC21: 2 | AD21: -1 | AE21: 3 | AF21: 16 | AG21: 3 | AH21: 8 | AI21: 11 | AJ21: -2 | AK21: -2 | AL21: 0 | AM21: 0 | AN21: 0 | AO21: 10 | AP21: 14 | AQ21: 13 | AR21: 8 | AS21: 6 | AT21: -4 | AU21: -6 | AV21: -12 | AW21: 0 | AX21: -14 | AY21: -14 | AZ21: 6 | BA21: 5 | BB21: -9 | BC21: 4 | BD21: -6 | BE21: 5 | BF21: -11 | BG21: -13 | BH21: -13 | BI21: -16 | BJ21: 0 | BK21: 0 | BL21: 0 | BM21: 8 | BN21: 7 | BO21: 8 | BP21: 5 | BQ21: -11 | BR21: -13 | BS21: -10 | BT21: -11 | BU21: -5 | BV21: 0 | BW21: 0 | BX21: 0 | BY21: 0 | BZ21: -5 | CA21: 0 | CB21: -10 | CC21: 0 | CD21: 0 | CE21: -8
B22: Textile Mills | D22: =IF(COUNTIF(S22:X22,">0")=0,(COUNTIF(S22:X22,"<0")*-1),COUNTIF(S22:X22,">0")) -> 5 | E22: 13 | F22: 10 | G22: 10 | H22: 3 | I22: 9 | J22: -11 | K22: -10 | L22: -10 | M22: 3 | N22: -4 | O22: 9 | P22: -5 | Q22: -12 | R22: 0 | S22: 13 | T22: 11 | U22: 12 | V22: 3 | W22: -2 | X22: 14 | Y22: 4 | Z22: 2 | AA22: 16 | AB22: 17 | AC22: 17 | AD22: 13 | AE22: 7 | AF22: -1 | AG22: -2 | AH22: 10 | AI22: 14 | AJ22: 0 | AK22: 13 | AL22: 0 | AM22: 15 | AN22: 9 | AO22: 4 | AP22: 0 | AQ22: 14 | AR22: 4 | AS22: 0 | AT22: -6 | AU22: -7 | AV22: -9 | AW22: 0 | AX22: 0 | AY22: -11 | AZ22: -10 | BA22: 0 | BB22: -11 | BC22: -9 | BD22: -13 | BE22: -8 | BF22: 3 | BG22: -12 | BH22: -9 | BI22: -11 | BJ22: 3 | BK22: 0 | BL22: 9 | BM22: 6 | BN22: 4 | BO22: -9 | BP22: 0 | BQ22: -12 | BR22: 3 | BS22: -11 | BT22: 0 | BU22: -7 | BV22: 8 | BW22: -4 | BX22: 9 | BY22: 7 | BZ22: 0 | CA22: -6 | CB22: 4 | CC22: 7 | CD22: 3 | CE22: -12
B23: Transportation Equipment | D23: =IF(COUNTIF(S23:X23,">0")=0,(COUNTIF(S23:X23,"<0")*-1),COUNTIF(S23:X23,">0")) -> 4 | E23: -1 | F23: 0 | G23: -2 | H23: -5 | I23: -5 | J23: -5 | K23: -9 | L23: -8 | M23: -8 | N23: -3 | O23: -2 | P23: -4 | Q23: -13 | R23: -9 | S23: -4 | T23: -3 | U23: 1 | V23: 1 | W23: 3 | X23: 3 | Y23: 10 | Z23: 10 | AA23: 9 | AB23: 6 | AC23: 5 | AD23: 4 | AE23: 10 | AF23: 4 | AG23: 5 | AH23: 4 | AI23: 1 | AJ23: 1 | AK23: 3 | AL23: 7 | AM23: 13 | AN23: 8 | AO23: 11 | AP23: 9 | AQ23: 6 | AR23: 6 | AS23: 8 | AT23: 4 | AU23: 4 | AV23: 1 | AW23: -2 | AX23: 1 | AY23: 3 | AZ23: -1 | BA23: 1 | BB23: 2 | BC23: 1 | BD23: -3 | BE23: 4 | BF23: -1 | BG23: -1 | BH23: 1 | BI23: -2 | BJ23: 2 | BK23: 1 | BL23: 1 | BM23: 3 | BN23: -2 | BO23: -5 | BP23: -7 | BQ23: -6 | BR23: -8 | BS23: -9 | BT23: -7 | BU23: -2 | BV23: 3 | BW23: 1 | BX23: 3 | BY23: -2 | BZ23: -3 | CA23: -2 | CB23: -3 | CC23: -7 | CD23: -4 | CE23: 4
B24: Wood Products | D24: =IF(COUNTIF(S24:X24,">0")=0,(COUNTIF(S24:X24,"<0")*-1),COUNTIF(S24:X24,">0")) -> 6 | E24: -3 | F24: -3 | G24: -3 | H24: 9 | I24: 6 | J24: -13 | K24: 2 | L24: -13 | M24: -12 | N24: 7 | O24: 14 | P24: 7 | Q24: -5 | R24: 1 | S24: 12 | T24: 13 | U24: 15 | V24: 13 | W24: 7 | X24: 13 | Y24: 14 | Z24: 7 | AA24: 8 | AB24: 0 | AC24: 1 | AD24: 3 | AE24: 2 | AF24: 2 | AG24: 4 | AH24: -1 | AI24: -2 | AJ24: 0 | AK24: -3 | AL24: 0 | AM24: -1 | AN24: -2 | AO24: 1 | AP24: 0 | AQ24: -2 | AR24: -7 | AS24: -7 | AT24: -5 | AU24: -9 | AV24: -11 | AW24: -13 | AX24: -15 | AY24: -12 | AZ24: -7 | BA24: -10 | BB24: -14 | BC24: -10 | BD24: -12 | BE24: -3 | BF24: -6 | BG24: -8 | BH24: -2 | BI24: -8 | BJ24: -13 | BK24: -5 | BL24: 0 | BM24: -4 | BN24: -7 | BO24: -6 | BP24: -4 | BQ24: -5 | BR24: -11 | BS24: 0 | BT24: 0 | BU24: 5 | BV24: -6 | BW24: 7 | BX24: -7 | BY24: -6 | BZ24: -6 | CA24: -5 | CB24: -6 | CC24: -9 | CD24: -11 | CE24: -7
B25: PMI Rank | H25: =AVERAGE(H26:H43) -> -1.5 | I25: =AVERAGE(I26:I43) -> -3.3333333 | J25: =AVERAGE(J26:J43) -> -3.3333333 | K25: =AVERAGE(K26:K43) -> 9.5 | L25: =AVERAGE(L26:L43) -> 9.5 | M25: =AVERAGE(M26:M43) -> 9.5 | N25: =AVERAGE(N26:N43) -> 9.5 | O25: =AVERAGE(O26:O43) -> 9.5 | P25: =AVERAGE(P26:P43) -> 9.5
A26: PMI Rank | B26: Apparel, Leather & Allied Products | D26: =SUM(S26:X26) -> 71 | G26: -6 | H26: -10 | I26: -11 | J26: -11 | K26: =_xlfn.RANK.AVG(K7,K$7:K$24,1) -> 2 | L26: =_xlfn.RANK.AVG(L7,L$7:L$24,1) -> 18 | M26: =_xlfn.RANK.AVG(M7,M$7:M$24,1) -> 14 | N26: =_xlfn.RANK.AVG(N7,N$7:N$24,1) -> 2 | O26: =_xlfn.RANK.AVG(O7,O$7:O$24,1) -> 4 | P26: =_xlfn.RANK.AVG(P7,P$7:P$24,1) -> 16 | Q26: =_xlfn.RANK.AVG(Q7,Q$7:Q$24,1) -> 16 | R26: =_xlfn.RANK.AVG(R7,R$7:R$24,1) -> 16 | ... T26: =_xlfn.RANK.AVG(T7,T$7:T$24,1) -> 11 | U26: =_xlfn.RANK.AVG(U7,$U$7:$U$24,1) -> 9 | V26: =_xlfn.RANK.AVG(V7,$V$7:$V$24,1) -> 1 | W26: =_xlfn.RANK.AVG(W7,W$7:W$24,1) -> 18 | X26: =_xlfn.RANK.AVG(X7,X$7:X$24,1) -> 18 | Y26: =_xlfn.RANK.AVG(Y7,Y$7:Y$24,1) -> 18 | Z26: =_xlfn.RANK.AVG(Z7,Z$7:Z$24,1) -> 11 | AA26: =_xlfn.RANK.AVG(AA7,AA$7:AA$24,1) -> 7 | AB26: =_xlfn.RANK.AVG(AB7,AB$7:AB$24,1) -> 14 | AC26: =_xlfn.RANK.AVG(AC7,AC$7:AC$24,1) -> 6 | AD26: =_xlfn.RANK.AVG(AD7,AD$7:AD$24,1) -> 2 | ... CE26: =_xlfn.RANK.AVG(CE7,CE$7:CE$24,1) -> 2
B27: Chemical Products | D27: =SUM(S27:X27) -> 66 | G27: 6 | H27: 2 | I27: 1 | J27: 1 | K27: =_xlfn.RANK.AVG(K8,K$7:K$24,1) -> 7 | L27: =_xlfn.RANK.AVG(L8,L$7:L$24,1) -> 12 | M27: =_xlfn.RANK.AVG(M8,M$7:M$24,1) -> 11 | N27: =_xlfn.RANK.AVG(N8,N$7:N$24,1) -> 12 | O27: =_xlfn.RANK.AVG(O8,O$7:O$24,1) -> 5 | P27: =_xlfn.RANK.AVG(P8,P$7:P$24,1) -> 13 | Q27: =_xlfn.RANK.AVG(Q8,Q$7:Q$24,1) -> 15 | R27: =_xlfn.RANK.AVG(R8,R$7:R$24,1) -> 9 | ... T27: =_xlfn.RANK.AVG(T8,T$7:T$24,1) -> 12 | U27: =_xlfn.RANK.AVG(U8,$U$7:$U$24,1) -> 14 | V27: =_xlfn.RANK.AVG(V8,$V$7:$V$24,1) -> 11 | W27: =_xlfn.RANK.AVG(W8,W$7:W$24,1) -> 9 | X27: =_xlfn.RANK.AVG(X8,X$7:X$24,1) -> 10 | Y27: =_xlfn.RANK.AVG(Y8,Y$7:Y$24,1) -> 9 | Z27: =_xlfn.RANK.AVG(Z8,Z$7:Z$24,1) -> 15 | AA27: =_xlfn.RANK.AVG(AA8,AA$7:AA$24,1) -> 14 | AB27: =_xlfn.RANK.AVG(AB8,AB$7:AB$24,1) -> 6 | AC27: =_xlfn.RANK.AVG(AC8,AC$7:AC$24,1) -> 11 | AD27: =_xlfn.RANK.AVG(AD8,AD$7:AD$24,1) -> 8 | ... CE27: =_xlfn.RANK.AVG(CE8,CE$7:CE$24,1) -> 9
B28: Computer & Electronic Products | D28: =SUM(S28:X28) -> 56 | G28: 1 | H28: 1 | I28: -1 | J28: -3 | K28: =_xlfn.RANK.AVG(K9,K$7:K$24,1) -> 14 | L28: =_xlfn.RANK.AVG(L9,L$7:L$24,1) -> 14 | M28: =_xlfn.RANK.AVG(M9,M$7:M$24,1) -> 10 | N28: =_xlfn.RANK.AVG(N9,N$7:N$24,1) -> 15 | O28: =_xlfn.RANK.AVG(O9,O$7:O$24,1) -> 10 | P28: =_xlfn.RANK.AVG(P9,P$7:P$24,1) -> 12 | Q28: =_xlfn.RANK.AVG(Q9,Q$7:Q$24,1) -> 13 | R28: =_xlfn.RANK.AVG(R9,R$7:R$24,1) -> 10 | ... T28: =_xlfn.RANK.AVG(T9,T$7:T$24,1) -> 10 | U28: =_xlfn.RANK.AVG(U9,$U$7:$U$24,1) -> 13 | V28: =_xlfn.RANK.AVG(V9,$V$7:$V$24,1) -> 6 | W28: =_xlfn.RANK.AVG(W9,W$7:W$24,1) -> 7 | X28: =_xlfn.RANK.AVG(X9,X$7:X$24,1) -> 8 | Y28: =_xlfn.RANK.AVG(Y9,Y$7:Y$24,1) -> 13 | Z28: =_xlfn.RANK.AVG(Z9,Z$7:Z$24,1) -> 3 | AA28: =_xlfn.RANK.AVG(AA9,AA$7:AA$24,1) -> 8 | AB28: =_xlfn.RANK.AVG(AB9,AB$7:AB$24,1) -> 15 | AC28: =_xlfn.RANK.AVG(AC9,AC$7:AC$24,1) -> 8 | AD28: =_xlfn.RANK.AVG(AD9,AD$7:AD$24,1) -> 13 | ... CE28: =_xlfn.RANK.AVG(CE9,CE$7:CE$24,1) -> 12
B29: Electrical Equipment, Appliances & Components | D29: =SUM(S29:X29) -> 51 | G29: 0 | H29: -6 | I29: 0 | J29: -8 | K29: =_xlfn.RANK.AVG(K10,K$7:K$24,1) -> 9 | L29: =_xlfn.RANK.AVG(L10,L$7:L$24,1) -> 13 | M29: =_xlfn.RANK.AVG(M10,M$7:M$24,1) -> 7 | N29: =_xlfn.RANK.AVG(N10,N$7:N$24,1) -> 3 | O29: =_xlfn.RANK.AVG(O10,O$7:O$24,1) -> 8 | P29: =_xlfn.RANK.AVG(P10,P$7:P$24,1) -> 7.5 | Q29: =_xlfn.RANK.AVG(Q10,Q$7:Q$24,1) -> 9 | R29: =_xlfn.RANK.AVG(R10,R$7:R$24,1) -> 8 | ... T29: =_xlfn.RANK.AVG(T10,T$7:T$24,1) -> 6 | U29: =_xlfn.RANK.AVG(U10,$U$7:$U$24,1) -> 6 | V29: =_xlfn.RANK.AVG(V10,$V$7:$V$24,1) -> 14 | W29: =_xlfn.RANK.AVG(W10,W$7:W$24,1) -> 5 | X29: =_xlfn.RANK.AVG(X10,X$7:X$24,1) -> 14 | Y29: =_xlfn.RANK.AVG(Y10,Y$7:Y$24,1) -> 5 | Z29: =_xlfn.RANK.AVG(Z10,Z$7:Z$24,1) -> 18 | AA29: =_xlfn.RANK.AVG(AA10,AA$7:AA$24,1) -> 17 | AB29: =_xlfn.RANK.AVG(AB10,AB$7:AB$24,1) -> 17 | AC29: =_xlfn.RANK.AVG(AC10,AC$7:AC$24,1) -> 18 | AD29: =_xlfn.RANK.AVG(AD10,AD$7:AD$24,1) -> 12 | ... CE29: =_xlfn.RANK.AVG(CE10,CE$7:CE$24,1) -> 8
B30: Fabricated Metal Products | D30: =SUM(S30:X30) -> 59 | G30: -1 | H30: -7 | I30: -6 | J30: -2 | K30: =_xlfn.RANK.AVG(K11,K$7:K$24,1) -> 10 | L30: =_xlfn.RANK.AVG(L11,L$7:L$24,1) -> 5 | M30: =_xlfn.RANK.AVG(M11,M$7:M$24,1) -> 6 | N30: =_xlfn.RANK.AVG(N11,N$7:N$24,1) -> 11 | O30: =_xlfn.RANK.AVG(O11,O$7:O$24,1) -> 7 | P30: =_xlfn.RANK.AVG(P11,P$7:P$24,1) -> 5 | Q30: =_xlfn.RANK.AVG(Q11,Q$7:Q$24,1) -> 5 | R30: =_xlfn.RANK.AVG(R11,R$7:R$24,1) -> 5 | ... T30: =_xlfn.RANK.AVG(T11,T$7:T$24,1) -> 3 | U30: =_xlfn.RANK.AVG(U11,$U$7:$U$24,1) -> 11 | V30: =_xlfn.RANK.AVG(V11,$V$7:$V$24,1) -> 12 | W30: =_xlfn.RANK.AVG(W11,W$7:W$24,1) -> 17 | X30: =_xlfn.RANK.AVG(X11,X$7:X$24,1) -> 13 | Y30: =_xlfn.RANK.AVG(Y11,Y$7:Y$24,1) -> 15 | Z30: =_xlfn.RANK.AVG(Z11,Z$7:Z$24,1) -> 14 | AA30: =_xlfn.RANK.AVG(AA11,AA$7:AA$24,1) -> 12 | AB30: =_xlfn.RANK.AVG(AB11,AB$7:AB$24,1) -> 12 | AC30: =_xlfn.RANK.AVG(AC11,AC$7:AC$24,1) -> 14 | AD30: =_xlfn.RANK.AVG(AD11,AD$7:AD$24,1) -> 11 | ... CE30: =_xlfn.RANK.AVG(CE11,CE$7:CE$24,1) -> 14
B31: Food, Beverage & Tobacco Products | D31: =SUM(S31:X31) -> 77 | G31: 5 | H31: 4 | I31: 0 | J31: 2 | K31: =_xlfn.RANK.AVG(K12,K$7:K$24,1) -> 16 | L31: =_xlfn.RANK.AVG(L12,L$7:L$24,1) -> 17 | M31: =_xlfn.RANK.AVG(M12,M$7:M$24,1) -> 17 | N31: =_xlfn.RANK.AVG(N12,N$7:N$24,1) -> 16 | O31: =_xlfn.RANK.AVG(O12,O$7:O$24,1) -> 11 | P31: =_xlfn.RANK.AVG(P12,P$7:P$24,1) -> 17 | Q31: =_xlfn.RANK.AVG(Q12,Q$7:Q$24,1) -> 17 | R31: =_xlfn.RANK.AVG(R12,R$7:R$24,1) -> 15 | ... T31: =_xlfn.RANK.AVG(T12,T$7:T$24,1) -> 14 | U31: =_xlfn.RANK.AVG(U12,$U$7:$U$24,1) -> 16 | V31: =_xlfn.RANK.AVG(V12,$V$7:$V$24,1) -> 16 | W31: =_xlfn.RANK.AVG(W12,W$7:W$24,1) -> 15 | X31: =_xlfn.RANK.AVG(X12,X$7:X$24,1) -> 3 | Y31: =_xlfn.RANK.AVG(Y12,Y$7:Y$24,1) -> 4 | Z31: =_xlfn.RANK.AVG(Z12,Z$7:Z$24,1) -> 8 | AA31: =_xlfn.RANK.AVG(AA12,AA$7:AA$24,1) -> 6 | AB31: =_xlfn.RANK.AVG(AB12,AB$7:AB$24,1) -> 11 | AC31: =_xlfn.RANK.AVG(AC12,AC$7:AC$24,1) -> 9 | AD31: =_xlfn.RANK.AVG(AD12,AD$7:AD$24,1) -> 10 | ... CE31: =_xlfn.RANK.AVG(CE12,CE$7:CE$24,1) -> 17
B32: Furniture & Related Products | D32: =SUM(S32:X32) -> 67 | G32: 10 | H32: 7 | I32: 0 | J32: 0 | K32: =_xlfn.RANK.AVG(K13,K$7:K$24,1) -> 18 | L32: =_xlfn.RANK.AVG(L13,L$7:L$24,1) -> 3 | M32: =_xlfn.RANK.AVG(M13,M$7:M$24,1) -> 2 | N32: =_xlfn.RANK.AVG(N13,N$7:N$24,1) -> 18 | O32: =_xlfn.RANK.AVG(O13,O$7:O$24,1) -> 17 | P32: =_xlfn.RANK.AVG(P13,P$7:P$24,1) -> 4 | Q32: =_xlfn.RANK.AVG(Q13,Q$7:Q$24,1) -> 2 | R32: =_xlfn.RANK.AVG(R13,R$7:R$24,1) -> 17 | ... T32: =_xlfn.RANK.AVG(T13,T$7:T$24,1) -> 17 | U32: =_xlfn.RANK.AVG(U13,$U$7:$U$24,1) -> 3 | V32: =_xlfn.RANK.AVG(V13,$V$7:$V$24,1) -> 15 | W32: =_xlfn.RANK.AVG(W13,W$7:W$24,1) -> 12 | X32: =_xlfn.RANK.AVG(X13,X$7:X$24,1) -> 4 | Y32: =_xlfn.RANK.AVG(Y13,Y$7:Y$24,1) -> 17 | Z32: =_xlfn.RANK.AVG(Z13,Z$7:Z$24,1) -> 6 | AA32: =_xlfn.RANK.AVG(AA13,AA$7:AA$24,1) -> 4 | AB32: =_xlfn.RANK.AVG(AB13,AB$7:AB$24,1) -> 13 | AC32: =_xlfn.RANK.AVG(AC13,AC$7:AC$24,1) -> 16 | AD32: =_xlfn.RANK.AVG(AD13,AD$7:AD$24,1) -> 18 | ... CE32: =_xlfn.RANK.AVG(CE13,CE$7:CE$24,1) -> 3
B33: Machinery | D33: =SUM(S33:X33) -> 46 | G33: -2 | H33: 0 | I33: 2 | J33: 0 | K33: =_xlfn.RANK.AVG(K14,K$7:K$24,1) -> 6 | L33: =_xlfn.RANK.AVG(L14,L$7:L$24,1) -> 11 | M33: =_xlfn.RANK.AVG(M14,M$7:M$24,1) -> 12 | N33: =_xlfn.RANK.AVG(N14,N$7:N$24,1) -> 8 | O33: =_xlfn.RANK.AVG(O14,O$7:O$24,1) -> 6 | P33: =_xlfn.RANK.AVG(P14,P$7:P$24,1) -> 6 | Q33: =_xlfn.RANK.AVG(Q14,Q$7:Q$24,1) -> 7 | R33: =_xlfn.RANK.AVG(R14,R$7:R$24,1) -> 6 | ... T33: =_xlfn.RANK.AVG(T14,T$7:T$24,1) -> 2 | U33: =_xlfn.RANK.AVG(U14,$U$7:$U$24,1) -> 10 | V33: =_xlfn.RANK.AVG(V14,$V$7:$V$24,1) -> 8 | W33: =_xlfn.RANK.AVG(W14,W$7:W$24,1) -> 13 | X33: =_xlfn.RANK.AVG(X14,X$7:X$24,1) -> 9 | Y33: =_xlfn.RANK.AVG(Y14,Y$7:Y$24,1) -> 14 | Z33: =_xlfn.RANK.AVG(Z14,Z$7:Z$24,1) -> 17 | AA33: =_xlfn.RANK.AVG(AA14,AA$7:AA$24,1) -> 13 | AB33: =_xlfn.RANK.AVG(AB14,AB$7:AB$24,1) -> 16 | AC33: =_xlfn.RANK.AVG(AC14,AC$7:AC$24,1) -> 15 | AD33: =_xlfn.RANK.AVG(AD14,AD$7:AD$24,1) -> 9 | ... CE33: =_xlfn.RANK.AVG(CE14,CE$7:CE$24,1) -> 10
B34: Miscellaneous Manufacturing | D34: =SUM(S34:X34) -> 43 | G34: 3 | H34: -3 | I34: -2 | J34: 3 | K34: =_xlfn.RANK.AVG(K15,K$7:K$24,1) -> 11 | L34: =_xlfn.RANK.AVG(L15,L$7:L$24,1) -> 15 | M34: =_xlfn.RANK.AVG(M15,M$7:M$24,1) -> 16 | N34: =_xlfn.RANK.AVG(N15,N$7:N$24,1) -> 14 | O34: =_xlfn.RANK.AVG(O15,O$7:O$24,1) -> 9 | P34: =_xlfn.RANK.AVG(P15,P$7:P$24,1) -> 10 | Q34: =_xlfn.RANK.AVG(Q15,Q$7:Q$24,1) -> 12 | R34: =_xlfn.RANK.AVG(R15,R$7:R$24,1) -> 7 | ... T34: =_xlfn.RANK.AVG(T15,T$7:T$24,1) -> 7 | U34: =_xlfn.RANK.AVG(U15,$U$7:$U$24,1) -> 7 | V34: =_xlfn.RANK.AVG(V15,$V$7:$V$24,1) -> 10 | W34: =_xlfn.RANK.AVG(W15,W$7:W$24,1) -> 4 | X34: =_xlfn.RANK.AVG(X15,X$7:X$24,1) -> 6 | Y34: =_xlfn.RANK.AVG(Y15,Y$7:Y$24,1) -> 3 | Z34: =_xlfn.RANK.AVG(Z15,Z$7:Z$24,1) -> 5 | AA34: =_xlfn.RANK.AVG(AA15,AA$7:AA$24,1) -> 5 | AB34: =_xlfn.RANK.AVG(AB15,AB$7:AB$24,1) -> 4 | AC34: =_xlfn.RANK.AVG(AC15,AC$7:AC$24,1) -> 12 | AD34: =_xlfn.RANK.AVG(AD15,AD$7:AD$24,1) -> 7 | ... CE34: =_xlfn.RANK.AVG(CE15,CE$7:CE$24,1) -> 11
B35: Nonmetallic Mineral Products | D35: =SUM(S35:X35) -> 66.5 | G35: 9 | H35: -4 | I35: 3 | J35: -7 | K35: =_xlfn.RANK.AVG(K16,K$7:K$24,1) -> 13 | L35: =_xlfn.RANK.AVG(L16,L$7:L$24,1) -> 10 | M35: =_xlfn.RANK.AVG(M16,M$7:M$24,1) -> 3 | N35: =_xlfn.RANK.AVG(N16,N$7:N$24,1) -> 13 | O35: =_xlfn.RANK.AVG(O16,O$7:O$24,1) -> 3 | P35: =_xlfn.RANK.AVG(P16,P$7:P$24,1) -> 7.5 | Q35: =_xlfn.RANK.AVG(Q16,Q$7:Q$24,1) -> 6 | R35: =_xlfn.RANK.AVG(R16,R$7:R$24,1) -> 18 | ... T35: =_xlfn.RANK.AVG(T16,T$7:T$24,1) -> 4.5 | U35: =_xlfn.RANK.AVG(U16,$U$7:$U$24,1) -> 8 | V35: =_xlfn.RANK.AVG(V16,$V$7:$V$24,1) -> 13 | W35: =_xlfn.RANK.AVG(W16,W$7:W$24,1) -> 16 | X35: =_xlfn.RANK.AVG(X16,X$7:X$24,1) -> 17 | Y35: =_xlfn.RANK.AVG(Y16,Y$7:Y$24,1) -> 2 | Z35: =_xlfn.RANK.AVG(Z16,Z$7:Z$24,1) -> 7 | AA35: =_xlfn.RANK.AVG(AA16,AA$7:AA$24,1) -> 3 | AB35: =_xlfn.RANK.AVG(AB16,AB$7:AB$24,1) -> 5 | AC35: =_xlfn.RANK.AVG(AC16,AC$7:AC$24,1) -> 7 | AD35: =_xlfn.RANK.AVG(AD16,AD$7:AD$24,1) -> 17 | ... CE35: =_xlfn.RANK.AVG(CE16,CE$7:CE$24,1) -> 13
B36: Paper Products | D36: =SUM(S36:X36) -> 52.5 | G36: 2 | H36: -2 | I36: -10 | J36: -4 | K36: =_xlfn.RANK.AVG(K17,K$7:K$24,1) -> 12 | L36: =_xlfn.RANK.AVG(L17,L$7:L$24,1) -> 16 | M36: =_xlfn.RANK.AVG(M17,M$7:M$24,1) -> 8 | N36: =_xlfn.RANK.AVG(N17,N$7:N$24,1) -> 9.5 | O36: =_xlfn.RANK.AVG(O17,O$7:O$24,1) -> 14 | P36: =_xlfn.RANK.AVG(P17,P$7:P$24,1) -> 14 | Q36: =_xlfn.RANK.AVG(Q17,Q$7:Q$24,1) -> 18 | R36: =_xlfn.RANK.AVG(R17,R$7:R$24,1) -> 14 | ... T36: =_xlfn.RANK.AVG(T17,T$7:T$24,1) -> 4.5 | U36: =_xlfn.RANK.AVG(U17,$U$7:$U$24,1) -> 5 | V36: =_xlfn.RANK.AVG(V17,$V$7:$V$24,1) -> 18 | W36: =_xlfn.RANK.AVG(W17,W$7:W$24,1) -> 11 | X36: =_xlfn.RANK.AVG(X17,X$7:X$24,1) -> 7 | Y36: =_xlfn.RANK.AVG(Y17,Y$7:Y$24,1) -> 10 | Z36: =_xlfn.RANK.AVG(Z17,Z$7:Z$24,1) -> 10 | AA36: =_xlfn.RANK.AVG(AA17,AA$7:AA$24,1) -> 15 | AB36: =_xlfn.RANK.AVG(AB17,AB$7:AB$24,1) -> 8 | AC36: =_xlfn.RANK.AVG(AC17,AC$7:AC$24,1) -> 4 | AD36: =_xlfn.RANK.AVG(AD17,AD$7:AD$24,1) -> 4 | ... CE36: =_xlfn.RANK.AVG(CE17,CE$7:CE$24,1) -> 4
B37: Petroleum & Coal Products | D37: =SUM(S37:X37) -> 23 | G37: 0 | H37: -8 | I37: -5 | J37: -6 | K37: =_xlfn.RANK.AVG(K18,K$7:K$24,1) -> 8 | L37: =_xlfn.RANK.AVG(L18,L$7:L$24,1) -> 9 | M37: =_xlfn.RANK.AVG(M18,M$7:M$24,1) -> 14 | N37: =_xlfn.RANK.AVG(N18,N$7:N$24,1) -> 4 | O37: =_xlfn.RANK.AVG(O18,O$7:O$24,1) -> 1 | P37: =_xlfn.RANK.AVG(P18,P$7:P$24,1) -> 1 | Q37: =_xlfn.RANK.AVG(Q18,Q$7:Q$24,1) -> 10 | R37: =_xlfn.RANK.AVG(R18,R$7:R$24,1) -> 4 | ... T37: =_xlfn.RANK.AVG(T18,T$7:T$24,1) -> 8 | U37: =_xlfn.RANK.AVG(U18,$U$7:$U$24,1) -> 2 | V37: =_xlfn.RANK.AVG(V18,$V$7:$V$24,1) -> 3 | W37: =_xlfn.RANK.AVG(W18,W$7:W$24,1) -> 3 | X37: =_xlfn.RANK.AVG(X18,X$7:X$24,1) -> 2 | Y37: =_xlfn.RANK.AVG(Y18,Y$7:Y$24,1) -> 8 | Z37: =_xlfn.RANK.AVG(Z18,Z$7:Z$24,1) -> 2 | AA37: =_xlfn.RANK.AVG(AA18,AA$7:AA$24,1) -> 2 | AB37: =_xlfn.RANK.AVG(AB18,AB$7:AB$24,1) -> 2 | AC37: =_xlfn.RANK.AVG(AC18,AC$7:AC$24,1) -> 3 | AD37: =_xlfn.RANK.AVG(AD18,AD$7:AD$24,1) -> 3 | ... CE37: =_xlfn.RANK.AVG(CE18,CE$7:CE$24,1) -> 7
B38: Plastics & Rubber Products | D38: =SUM(S38:X38) -> 76 | G38: 4 | H38: -1 | I38: -4 | J38: -1 | K38: =_xlfn.RANK.AVG(K19,K$7:K$24,1) -> 5 | L38: =_xlfn.RANK.AVG(L19,L$7:L$24,1) -> 8 | M38: =_xlfn.RANK.AVG(M19,M$7:M$24,1) -> 14 | N38: =_xlfn.RANK.AVG(N19,N$7:N$24,1) -> 9.5 | O38: =_xlfn.RANK.AVG(O19,O$7:O$24,1) -> 16 | P38: =_xlfn.RANK.AVG(P19,P$7:P$24,1) -> 9 | Q38: =_xlfn.RANK.AVG(Q19,Q$7:Q$24,1) -> 8 | R38: =_xlfn.RANK.AVG(R19,R$7:R$24,1) -> 11 | ... T38: =_xlfn.RANK.AVG(T19,T$7:T$24,1) -> 13 | U38: =_xlfn.RANK.AVG(U19,$U$7:$U$24,1) -> 17 | V38: =_xlfn.RANK.AVG(V19,$V$7:$V$24,1) -> 9 | W38: =_xlfn.RANK.AVG(W19,W$7:W$24,1) -> 14 | X38: =_xlfn.RANK.AVG(X19,X$7:X$24,1) -> 12 | Y38: =_xlfn.RANK.AVG(Y19,Y$7:Y$24,1) -> 11 | Z38: =_xlfn.RANK.AVG(Z19,Z$7:Z$24,1) -> 13 | AA38: =_xlfn.RANK.AVG(AA19,AA$7:AA$24,1) -> 9 | AB38: =_xlfn.RANK.AVG(AB19,AB$7:AB$24,1) -> 9 | AC38: =_xlfn.RANK.AVG(AC19,AC$7:AC$24,1) -> 10 | AD38: =_xlfn.RANK.AVG(AD19,AD$7:AD$24,1) -> 16 | ... CE38: =_xlfn.RANK.AVG(CE19,CE$7:CE$24,1) -> 15
... B43: Wood Products | D43: =SUM(S43:X43) -> 95 | G43: -4 | H43: 6 | I43: -9 | J43: -9 | K43: =_xlfn.RANK.AVG(K24,K$7:K$24,1) -> 15 | L43: =_xlfn.RANK.AVG(L24,L$7:L$24,1) -> 1 | M43: =_xlfn.RANK.AVG(M24,M$7:M$24,1) -> 1 | N43: =_xlfn.RANK.AVG(N24,N$7:N$24,1) -> 17 | O43: =_xlfn.RANK.AVG(O24,O$7:O$24,1) -> 18 | P43: =_xlfn.RANK.AVG(P24,P$7:P$24,1) -> 15 | Q43: =_xlfn.RANK.AVG(Q24,Q$7:Q$24,1) -> 11 | R43: =_xlfn.RANK.AVG(R24,R$7:R$24,1) -> 13 | ... T43: =_xlfn.RANK.AVG(T24,T$7:T$24,1) -> 18 | U43: =_xlfn.RANK.AVG(U24,$U$7:$U$24,1) -> 18 | V43: =_xlfn.RANK.AVG(V24,$V$7:$V$24,1) -> 17 | W43: =_xlfn.RANK.AVG(W24,W$7:W$24,1) -> 10 | X43: =_xlfn.RANK.AVG(X24,X$7:X$24,1) -> 15 | Y43: =_xlfn.RANK.AVG(Y24,Y$7:Y$24,1) -> 16 | Z43: =_xlfn.RANK.AVG(Z24,Z$7:Z$24,1) -> 9 | AA43: =_xlfn.RANK.AVG(AA24,AA$7:AA$24,1) -> 10 | AB43: =_xlfn.RANK.AVG(AB24,AB$7:AB$24,1) -> 1 | AC43: =_xlfn.RANK.AVG(AC24,AC$7:AC$24,1) -> 1 | AD43: =_xlfn.RANK.AVG(AD24,AD$7:AD$24,1) -> 5 | ... CE43: =_xlfn.RANK.AVG(CE24,CE$7:CE$24,1) -> 6
B44: New Orders | H44: =AVERAGE(H45:H62) -> -1.5 | I44: =AVERAGE(I45:I62) -> -3.3333333 | J44: =AVERAGE(J45:J62) -> -3.3333333 | K44: =AVERAGE(K45:K62) -> -2.2222222 | L44: =AVERAGE(L45:L62) -> -3.5 | M44: =AVERAGE(M45:M62) -> -4 | N44: =AVERAGE(N45:N62) -> 2.2222222 | O44: =AVERAGE(O45:O62) -> 7.3888889 | P44: =AVERAGE(P45:P62) -> 0
...

Sheet industry notes
B2: Basic Materials | C2: Conglomerates | D2: Consumer Goods | E2: Financial | F2: Healthcare | G2: Industrial Goods | H2: Services | K2: Technology | L2: Utilities
B4: Agricultural Chemicals | C4: Conglomerates | D4: Appliances | E4: Accident & Health Insurance | F4: Biotechnology | G4: Aerospace/Defense - Major Diversified | H4: Advertising Agencies | I4: Publishing - Books | K4: Application Software | L4: Diversified Utilities
B5: Aluminum | D5: Auto Manufacturers - Major | E5: Asset Management | F5: Diagnostic Substances | G5: Aerospace/Defense Products & Services | H5: Air Delivery & Freight Services | I5: Publishing - Newspapers | K5: Business Software & Services | L5: Electric Utilities
B6: Chemicals - Major Diversified | D6: Auto Parts | E6: Closed-End Fund - Debt | F6: Drug Delivery | G6: Cement | H6: Air Services, Other | I6: Publishing - Periodicals | K6: Communication Equipment | L6: Foreign Utilities
B7: Copper | D7: Beverages - Brewers | E7: Closed-End Fund - Equity | F7: Drug Manufacturers - Major | G7: Diversified Machinery | H7: Apparel Stores | I7: Railroads | K7: Computer Based Systems | L7: Gas Utilities
B8: Gold | D8: Beverages - Soft Drinks | E8: Closed-End Fund - Foreign | F8: Drug Manufacturers - Other | G8: Farm & Construction Machinery | H8: Auto Dealerships | I8: Regional Airlines | K8: Computer Peripherals | L8: Water Utilities
B9: Independent Oil & Gas | D9: Beverages - Wineries & Distillers | E9: Credit Services | F9: Drug Related Products | G9: General Building Materials | H9: Auto Parts Stores | I9: Rental & Leasing Services | K9: Data Storage Devices
B10: Industrial Metals & Minerals | D10: Business Equipment | E10: Diversified Investments | F10: Drugs - Generic | G10: General Contractors | H10: Auto Parts Wholesale | I10: Research Services | K10: Diversified Communication Services
B11: Major Integrated Oil & Gas | D11: Cigarettes | E11: Foreign Money Center Banks | F11: Health Care Plans | G11: Heavy Construction | H11: Basic Materials Wholesale | I11: Resorts & Casinos | K11: Diversified Computer Systems
B12: Nonmetallic Mineral Mining | D12: Cleaning Products | E12: Foreign Regional Banks | F12: Home Health Care | G12: Industrial Electrical Equipment | H12: Broadcasting - Radio | I12: Restaurants | K12: Diversified Electronics
B13: Oil & Gas Drilling & Exploration | D13: Confectioners | E13: Insurance Brokers | F13: Hospitals | G13: Industrial Equipment & Components | H13: Broadcasting - TV | I13: Security & Protection Services | K13: Healthcare Information Services
B14: Oil & Gas Equipment & Services | D14: Dairy Products | E14: Investment Brokerage - National | F14: Long-Term Care Facilities | G14: Lumber, Wood Production | H14: Building Materials Wholesale | I14: Shipping | K14: Information & Delivery Services
B15: Oil & Gas Pipelines | D15: Electronic Equipment | E15: Investment Brokerage - Regional | F15: Medical Appliances & Equipment | G15: Machine Tools & Accessories | H15: Business Services | I15: Specialty Eateries | K15: Information Technology Services
B16: Oil & Gas Refining & Marketing | D16: Farm Products | E16: Life Insurance | F16: Medical Instruments & Supplies | G16: Manufactured Housing | H16: Catalog & Mail Order Houses | I16: Specialty Retail, Other | K16: Internet Information Providers
B17: Silver | D17: Food - Major Diversified | E17: Money Center Banks | F17: Medical Laboratories & Research | G17: Metal Fabrication | H17: CATV Systems | I17: Sporting Activities | K17: Internet Service Providers
B18: Specialty Chemicals | D18: Home Furnishings & Fixtures | E18: Mortgage Investment | F18: Medical Practitioners | G18: Pollution & Treatment Controls | H18: Computers Wholesale | I18: Sporting Goods Stores | K18: Internet Software & Services
B19: Steel & Iron | D19: Housewares & Accessories | E19: Property & Casualty Insurance | F19: Specialized Health Services | G19: Residential Construction | H19: Consumer Services | I19: Staffing & Outsourcing Services | K19: Long Distance Carriers
B20: Synthetics | D20: Meat Products | E20: Property Management | G20: Small Tools & Accessories | H20: Department Stores | I20: Technical Services | K20: Multimedia & Graphics Software
D21: Office Supplies | E21: Real Estate Development | G21: Textile Industrial | H21: Discount, Variety Stores | I21: Toy & Hobby Stores | K21: Networking & Communication Devices
D22: Packaging & Containers | E22: Regional - Mid-Atlantic Banks | G22: Waste Management | H22: Drug Stores | I22: Trucking | K22: Personal Computers
D23: Paper & Paper Products | E23: Regional - Midwest Banks | H23: Drugs Wholesale | I23: Wholesale, Other | K23: Printed Circuit Boards
D24: Personal Products | E24: Regional - Northeast Banks | H24: Education & Training Services | K24: Processing Systems & Products
D25: Photographic Equipment & Supplies | E25: Regional - Pacific Banks | H25: Electronics Stores | K25: Scientific & Technical Instruments
D26: Processed & Packaged Goods | E26: Regional - Southeast Banks | H26: Electronics Wholesale | K26: Security Software & Services
D27: Recreational Goods, Other | E27: Regional - Southwest Banks | H27: Entertainment - Diversified | K27: Semiconductor - Broad Line
D28: Recreational Vehicles | E28: REIT - Diversified | H28: Food Wholesale | K28: Semiconductor - Integrated Circuits
D29: Rubber & Plastics | E29: REIT - Healthcare Facilities | H29: Gaming Activities | K29: Semiconductor - Specialized
D30: Sporting Goods | E30: REIT - Hotel/Motel | H30: General Entertainment | K30: Semiconductor Equipment & Materials
D31: Textile - Apparel Clothing | E31: REIT - Industrial | H31: Grocery Stores | K31: Semiconductor- Memory Chips
D32: Textile - Apparel Footwear & Accessories | E32: REIT - Office | H32: Home Furnishing Stores | K32: Technical & System Software
D33: Tobacco Products, Other | E33: REIT - Residential | H33: Home Improvement Stores | K33: Telecom Services - Domestic
D34: Toys & Games | E34: REIT - Retail | H34: Industrial Equipment Wholesale | K34: Telecom Services - Foreign
D35: Trucks & Other Vehicles | E35: Savings & Loans | H35: Jewelry Stores | K35: Wireless Communications
E36: Surety & Title Insurance | H36: Lodging
H37: Major Airlines
H38: Management Services
H39: Marketing Services
H40: Medical Equipment Wholesale
H41: Movie Production, Theaters
B42: Use this spreadsheet to drill down through the sector level and analyse stocks within sectors | H42: Music & Video Stores
...

Sheet manu_pmi
A1: dates | B1: Apparel, Leather & Allied Products_pmi | C1: Chemical Products_pmi | D1: Computer & Electronic Products_pmi | E1: Electrical Equipment, Appliances & Components_pmi | F1: Fabricated Metal Products_pmi | G1: Food, Beverage & Tobacco Products_pmi | H1: Furniture & Related Products_pmi | I1: Machinery_pmi | J1: Miscellaneous Manufacturing_pmi | K1: Nonmetallic Mineral Products_pmi | L1: Paper Products_pmi | M1: Petroleum & Coal Products_pmi | N1: Plastics & Rubber Products_pmi | O1: Primary Metals_pmi | P1: Printing & Related Support Activities_pmi | Q1: Textile Mills_pmi | R1: Transportation Equipment_pmi | S1: Wood Products_pmi
A2: 43831 | B2: -7 | C2: 2 | D2: 5 | E2: -6 | F2: 1 | G2: 6 | H2: 8 | I2: -1 | J2: 4 | K2: 3 | L2: 0 | M2: -5 | N2: 0 | O2: -2 | P2: -8 | Q2: -4 | R2: -3 | S2: 7
A3: 43862 | B3: 0 | C3: 1 | D3: 6 | E3: 4 | F3: 3 | G3: 7 | H3: 13 | I3: 2 | J3: 5 | K3: -1 | L3: 10 | M3: -3 | N3: 12 | O3: 8 | P3: 11 | Q3: 9 | R3: -2 | S3: 14
A4: 43891 | B4: 8 | C4: 5 | D4: 4 | E4: 0 | F4: -2 | G4: 9 | H4: -3 | I4: -1 | J4: 2 | K4: 0 | L4: 6 | M4: -6 | N4: 1 | O4: 3 | P4: 10 | Q4: -5 | R4: -4 | S4: 7
A5: 43922 | B5: 0 | C5: -1 | D5: -3 | E5: -7 | F5: -11 | G5: 1 | H5: -14 | I5: -9 | J5: -4 | K5: -10 | L5: 2 | M5: -6 | N5: -8 | O5: -2 | P5: -15 | Q5: -12 | R5: -13 | S5: -5
A6: 43952 | B6: 4 | C6: -3 | D6: -2 | E6: -4 | F6: -7 | G6: 3 | H6: 5 | I6: -6 | J6: -5 | K6: 6 | L6: 2 | M6: -8 | N6: -1 | O6: -10 | P6: -11 | Q6: 0 | R6: -9 | S6: 1
A7: 43983 | B7: 9 | C7: 5 | D7: 7 | E7: 1 | F7: -2 | G7: 8 | H7: 11 | I7: -1 | J7: 4 | K7: 3 | L7: 2 | M7: 0 | N7: 6 | O7: -3 | P7: 10 | Q7: 13 | R7: -4 | S7: 12
A8: 44013 | B8: 6 | C8: 7 | D8: 5 | E8: 1 | F8: -1 | G8: 9 | H8: 12 | I8: -2 | J8: 2 | K8: 0 | L8: 0 | M8: 3 | N8: 8 | O8: 4 | P8: 10 | Q8: 11 | R8: -3 | S8: 13
A9: 44044 | B9: 6 | C9: 11 | D9: 10 | E9: 3 | F9: 8 | G9: 13 | H9: -1 | I9: 7 | J9: 4 | K9: 5 | L9: 2 | M9: -2 | N9: 14 | O9: 9 | P9: -3 | Q9: 12 | R9: 1 | S9: 15
A10: 44094 | B10: -4 | C10: 7 | D10: 2 | E10: 10 | F10: 8 | G10: 12 | H10: 11 | I10: 4 | J10: 6 | K10: 9 | L10: 14 | M10: -2 | N10: 5 | O10: -1 | P10: -3 | Q10: 3 | R10: 1 | S10: 13
A11: 44105 | B11: 15 | C11: 6 | D11: 4 | E11: 2 | F11: 14 | G11: 12 | H11: 9 | I11: 10 | J11: 1 | K11: 13 | L11: 8 | M11: 0 | N11: 11 | O11: 5 | P11: -1 | Q11: -2 | R11: 3 | S11: 7
A12: 44136 | B12: 16 | C12: 8 | D12: 6 | E12: 12 | F12: 11 | G12: 1 | H12: 2 | I12: 7 | J12: 4 | K12: 15 | L12: 5 | M12: -1 | N12: 10 | O12: 9 | P12: -2 | Q12: 14 | R12: 3 | S12: 13
A13: 44166 | B13: 16 | C13: 7 | D13: 11 | E13: 3 | F13: 13 | G13: 2 | H13: 15 | I13: 12 | J13: 1 | K13: -1 | L13: 8 | M13: 6 | N13: 9 | O13: 5 | P13: -2 | Q13: 4 | R13: 10 | S13: 14
... A71: 45931 | B71: -11 | C71: -4 | D71: -1 | E71: -5 | F71: 2 | G71: 5 | H71: -10 | I71: -3 | J71: -2 | K71: 1 | L71: -9 | M71: -6 | N71: 3 | O71: 6 | P71: -8 | Q71: -12 | R71: 4 | S71: -7

Sheet manu_rank
A1: dates | B1: Apparel, Leather & Allied Products_rnk | C1: Chemical Products_rnk | D1: Computer & Electronic Products_rnk | E1: Electrical Equipment, Appliances & Components_rnk | F1: Fabricated Metal Products_rnk | G1: Food, Beverage & Tobacco Products_rnk | H1: Furniture & Related Products_rnk | I1: Machinery_rnk | J1: Miscellaneous Manufacturing_rnk | K1: Nonmetallic Mineral Products_rnk | L1: Paper Products_rnk | M1: Petroleum & Coal Products_rnk | N1: Plastics & Rubber Products_rnk | O1: Primary Metals_rnk | P1: Printing & Related Support Activities_rnk | Q1: Textile Mills_rnk | R1: Transportation Equipment_rnk | S1: Wood Products_rnk
A2: 43831 | B2: =_xlfn.RANK.AVG(manu_pmi!B2,manu_pmi!$B2:$S2,1) -> 2 | C2: =_xlfn.RANK.AVG(manu_pmi!C2,manu_pmi!$B2:$S2,1) -> 12 | D2: =_xlfn.RANK.AVG(manu_pmi!D2,manu_pmi!$B2:$S2,1) -> 15 | E2: =_xlfn.RANK.AVG(manu_pmi!E2,manu_pmi!$B2:$S2,1) -> 3 | F2: =_xlfn.RANK.AVG(manu_pmi!F2,manu_pmi!$B2:$S2,1) -> 11 | G2: =_xlfn.RANK.AVG(manu_pmi!G2,manu_pmi!$B2:$S2,1) -> 16 | H2: =_xlfn.RANK.AVG(manu_pmi!H2,manu_pmi!$B2:$S2,1) -> 18 | I2: =_xlfn.RANK.AVG(manu_pmi!I2,manu_pmi!$B2:$S2,1) -> 8 | ... S2: =_xlfn.RANK.AVG(manu_pmi!S2,manu_pmi!$B2:$S2,1) -> 17
A3: 43862 | B3: =_xlfn.RANK.AVG(manu_pmi!B3,manu_pmi!$B3:$S3,1) -> 4 | C3: =_xlfn.RANK.AVG(manu_pmi!C3,manu_pmi!$B3:$S3,1) -> 5 | D3: =_xlfn.RANK.AVG(manu_pmi!D3,manu_pmi!$B3:$S3,1) -> 10 | E3: =_xlfn.RANK.AVG(manu_pmi!E3,manu_pmi!$B3:$S3,1) -> 8 | F3: =_xlfn.RANK.AVG(manu_pmi!F3,manu_pmi!$B3:$S3,1) -> 7 | G3: =_xlfn.RANK.AVG(manu_pmi!G3,manu_pmi!$B3:$S3,1) -> 11 | H3: =_xlfn.RANK.AVG(manu_pmi!H3,manu_pmi!$B3:$S3,1) -> 17 | I3: =_xlfn.RANK.AVG(manu_pmi!I3,manu_pmi!$B3:$S3,1) -> 6 | ... S3: =_xlfn.RANK.AVG(manu_pmi!S3,manu_pmi!$B3:$S3,1) -> 18
A4: 43891 | B4: =_xlfn.RANK.AVG(manu_pmi!B4,manu_pmi!$B4:$S4,1) -> 16 | C4: =_xlfn.RANK.AVG(manu_pmi!C4,manu_pmi!$B4:$S4,1) -> 13 | D4: =_xlfn.RANK.AVG(manu_pmi!D4,manu_pmi!$B4:$S4,1) -> 12 | E4: =_xlfn.RANK.AVG(manu_pmi!E4,manu_pmi!$B4:$S4,1) -> 7.5 | F4: =_xlfn.RANK.AVG(manu_pmi!F4,manu_pmi!$B4:$S4,1) -> 5 | G4: =_xlfn.RANK.AVG(manu_pmi!G4,manu_pmi!$B4:$S4,1) -> 17 | H4: =_xlfn.RANK.AVG(manu_pmi!H4,manu_pmi!$B4:$S4,1) -> 4 | I4: =_xlfn.RANK.AVG(manu_pmi!I4,manu_pmi!$B4:$S4,1) -> 6 | ... S4: =_xlfn.RANK.AVG(manu_pmi!S4,manu_pmi!$B4:$S4,1) -> 15
A5: 43922 | B5: =_xlfn.RANK.AVG(manu_pmi!B5,manu_pmi!$B5:$S5,1) -> 16 | C5: =_xlfn.RANK.AVG(manu_pmi!C5,manu_pmi!$B5:$S5,1) -> 15 | D5: =_xlfn.RANK.AVG(manu_pmi!D5,manu_pmi!$B5:$S5,1) -> 13 | E5: =_xlfn.RANK.AVG(manu_pmi!E5,manu_pmi!$B5:$S5,1) -> 9 | F5: =_xlfn.RANK.AVG(manu_pmi!F5,manu_pmi!$B5:$S5,1) -> 5 | G5: =_xlfn.RANK.AVG(manu_pmi!G5,manu_pmi!$B5:$S5,1) -> 17 | H5: =_xlfn.RANK.AVG(manu_pmi!H5,manu_pmi!$B5:$S5,1) -> 2 | I5: =_xlfn.RANK.AVG(manu_pmi!I5,manu_pmi!$B5:$S5,1) -> 7 | ... S5: =_xlfn.RANK.AVG(manu_pmi!S5,manu_pmi!$B5:$S5,1) -> 11
A6: 43952 | B6: =_xlfn.RANK.AVG(manu_pmi!B6,manu_pmi!$B6:$S6,1) -> 16 | C6: =_xlfn.RANK.AVG(manu_pmi!C6,manu_pmi!$B6:$S6,1) -> 9 | D6: =_xlfn.RANK.AVG(manu_pmi!D6,manu_pmi!$B6:$S6,1) -> 10 | E6: =_xlfn.RANK.AVG(manu_pmi!E6,manu_pmi!$B6:$S6,1) -> 8 | F6: =_xlfn.RANK.AVG(manu_pmi!F6,manu_pmi!$B6:$S6,1) -> 5 | G6: =_xlfn.RANK.AVG(manu_pmi!G6,manu_pmi!$B6:$S6,1) -> 15 | H6: =_xlfn.RANK.AVG(manu_pmi!H6,manu_pmi!$B6:$S6,1) -> 17 | I6: =_xlfn.RANK.AVG(manu_pmi!I6,manu_pmi!$B6:$S6,1) -> 6 | ... S6: =_xlfn.RANK.AVG(manu_pmi!S6,manu_pmi!$B6:$S6,1) -> 13
A7: 43983 | B7: =_xlfn.RANK.AVG(manu_pmi!B7,manu_pmi!$B7:$S7,1) -> 14 | C7: =_xlfn.RANK.AVG(manu_pmi!C7,manu_pmi!$B7:$S7,1) -> 10 | D7: =_xlfn.RANK.AVG(manu_pmi!D7,manu_pmi!$B7:$S7,1) -> 12 | E7: =_xlfn.RANK.AVG(manu_pmi!E7,manu_pmi!$B7:$S7,1) -> 6 | F7: =_xlfn.RANK.AVG(manu_pmi!F7,manu_pmi!$B7:$S7,1) -> 3 | G7: =_xlfn.RANK.AVG(manu_pmi!G7,manu_pmi!$B7:$S7,1) -> 13 | H7: =_xlfn.RANK.AVG(manu_pmi!H7,manu_pmi!$B7:$S7,1) -> 16 | I7: =_xlfn.RANK.AVG(manu_pmi!I7,manu_pmi!$B7:$S7,1) -> 4 | ... S7: =_xlfn.RANK.AVG(manu_pmi!S7,manu_pmi!$B7:$S7,1) -> 17
A8: 44013 | B8: =_xlfn.RANK.AVG(manu_pmi!B8,manu_pmi!$B8:$S8,1) -> 11 | C8: =_xlfn.RANK.AVG(manu_pmi!C8,manu_pmi!$B8:$S8,1) -> 12 | D8: =_xlfn.RANK.AVG(manu_pmi!D8,manu_pmi!$B8:$S8,1) -> 10 | E8: =_xlfn.RANK.AVG(manu_pmi!E8,manu_pmi!$B8:$S8,1) -> 6 | F8: =_xlfn.RANK.AVG(manu_pmi!F8,manu_pmi!$B8:$S8,1) -> 3 | G8: =_xlfn.RANK.AVG(manu_pmi!G8,manu_pmi!$B8:$S8,1) -> 14 | H8: =_xlfn.RANK.AVG(manu_pmi!H8,manu_pmi!$B8:$S8,1) -> 17 | I8: =_xlfn.RANK.AVG(manu_pmi!I8,manu_pmi!$B8:$S8,1) -> 2 | ... S8: =_xlfn.RANK.AVG(manu_pmi!S8,manu_pmi!$B8:$S8,1) -> 18
A9: 44044 | B9: =_xlfn.RANK.AVG(manu_pmi!B9,manu_pmi!$B9:$S9,1) -> 9 | C9: =_xlfn.RANK.AVG(manu_pmi!C9,manu_pmi!$B9:$S9,1) -> 14 | D9: =_xlfn.RANK.AVG(manu_pmi!D9,manu_pmi!$B9:$S9,1) -> 13 | E9: =_xlfn.RANK.AVG(manu_pmi!E9,manu_pmi!$B9:$S9,1) -> 6 | F9: =_xlfn.RANK.AVG(manu_pmi!F9,manu_pmi!$B9:$S9,1) -> 11 | G9: =_xlfn.RANK.AVG(manu_pmi!G9,manu_pmi!$B9:$S9,1) -> 16 | H9: =_xlfn.RANK.AVG(manu_pmi!H9,manu_pmi!$B9:$S9,1) -> 3 | I9: =_xlfn.RANK.AVG(manu_pmi!I9,manu_pmi!$B9:$S9,1) -> 10 | ... S9: =_xlfn.RANK.AVG(manu_pmi!S9,manu_pmi!$B9:$S9,1) -> 18
A10: 44094 | B10: =_xlfn.RANK.AVG(manu_pmi!B10,manu_pmi!$B10:$S10,1) -> 1 | C10: =_xlfn.RANK.AVG(manu_pmi!C10,manu_pmi!$B10:$S10,1) -> 11 | D10: =_xlfn.RANK.AVG(manu_pmi!D10,manu_pmi!$B10:$S10,1) -> 6 | E10: =_xlfn.RANK.AVG(manu_pmi!E10,manu_pmi!$B10:$S10,1) -> 14 | F10: =_xlfn.RANK.AVG(manu_pmi!F10,manu_pmi!$B10:$S10,1) -> 12 | G10: =_xlfn.RANK.AVG(manu_pmi!G10,manu_pmi!$B10:$S10,1) -> 16 | H10: =_xlfn.RANK.AVG(manu_pmi!H10,manu_pmi!$B10:$S10,1) -> 15 | I10: =_xlfn.RANK.AVG(manu_pmi!I10,manu_pmi!$B10:$S10,1) -> 8 | ... S10: =_xlfn.RANK.AVG(manu_pmi!S10,manu_pmi!$B10:$S10,1) -> 17
A11: 44105 | B11: =_xlfn.RANK.AVG(manu_pmi!B11,manu_pmi!$B11:$S11,1) -> 18 | C11: =_xlfn.RANK.AVG(manu_pmi!C11,manu_pmi!$B11:$S11,1) -> 9 | D11: =_xlfn.RANK.AVG(manu_pmi!D11,manu_pmi!$B11:$S11,1) -> 7 | E11: =_xlfn.RANK.AVG(manu_pmi!E11,manu_pmi!$B11:$S11,1) -> 5 | F11: =_xlfn.RANK.AVG(manu_pmi!F11,manu_pmi!$B11:$S11,1) -> 17 | G11: =_xlfn.RANK.AVG(manu_pmi!G11,manu_pmi!$B11:$S11,1) -> 15 | H11: =_xlfn.RANK.AVG(manu_pmi!H11,manu_pmi!$B11:$S11,1) -> 12 | I11: =_xlfn.RANK.AVG(manu_pmi!I11,manu_pmi!$B11:$S11,1) -> 13 | ... S11: =_xlfn.RANK.AVG(manu_pmi!S11,manu_pmi!$B11:$S11,1) -> 10
A12: 44136 | B12: =_xlfn.RANK.AVG(manu_pmi!B12,manu_pmi!$B12:$S12,1) -> 18 | C12: =_xlfn.RANK.AVG(manu_pmi!C12,manu_pmi!$B12:$S12,1) -> 10 | D12: =_xlfn.RANK.AVG(manu_pmi!D12,manu_pmi!$B12:$S12,1) -> 8 | E12: =_xlfn.RANK.AVG(manu_pmi!E12,manu_pmi!$B12:$S12,1) -> 14 | F12: =_xlfn.RANK.AVG(manu_pmi!F12,manu_pmi!$B12:$S12,1) -> 13 | G12: =_xlfn.RANK.AVG(manu_pmi!G12,manu_pmi!$B12:$S12,1) -> 3 | H12: =_xlfn.RANK.AVG(manu_pmi!H12,manu_pmi!$B12:$S12,1) -> 4 | I12: =_xlfn.RANK.AVG(manu_pmi!I12,manu_pmi!$B12:$S12,1) -> 9 | ... S12: =_xlfn.RANK.AVG(manu_pmi!S12,manu_pmi!$B12:$S12,1) -> 15
A13: 44166 | B13: =_xlfn.RANK.AVG(manu_pmi!B13,manu_pmi!$B13:$S13,1) -> 18 | C13: =_xlfn.RANK.AVG(manu_pmi!C13,manu_pmi!$B13:$S13,1) -> 9 | D13: =_xlfn.RANK.AVG(manu_pmi!D13,manu_pmi!$B13:$S13,1) -> 13 | E13: =_xlfn.RANK.AVG(manu_pmi!E13,manu_pmi!$B13:$S13,1) -> 5 | F13: =_xlfn.RANK.AVG(manu_pmi!F13,manu_pmi!$B13:$S13,1) -> 15 | G13: =_xlfn.RANK.AVG(manu_pmi!G13,manu_pmi!$B13:$S13,1) -> 4 | H13: =_xlfn.RANK.AVG(manu_pmi!H13,manu_pmi!$B13:$S13,1) -> 17 | I13: =_xlfn.RANK.AVG(manu_pmi!I13,manu_pmi!$B13:$S13,1) -> 14 | ... S13: =_xlfn.RANK.AVG(manu_pmi!S13,manu_pmi!$B13:$S13,1) -> 16
... A36: 44866 | B36: =_xlfn.RANK.AVG(manu_pmi!B36,manu_pmi!$B36:$S36,1) -> 18 | C36: =_xlfn.RANK.AVG(manu_pmi!C36,manu_pmi!$B36:$S36,1) -> 7 | D36: =_xlfn.RANK.AVG(manu_pmi!D36,manu_pmi!$B36:$S36,1) -> 9 | E36: =_xlfn.RANK.AVG(manu_pmi!E36,manu_pmi!$B36:$S36,1) -> 12 | F36: =_xlfn.RANK.AVG(manu_pmi!F36,manu_pmi!$B36:$S36,1) -> 5 | G36: =_xlfn.RANK.AVG(manu_pmi!G36,manu_pmi!$B36:$S36,1) -> 10 | H36: =_xlfn.RANK.AVG(manu_pmi!H36,manu_pmi!$B36:$S36,1) -> 6 | I36: =_xlfn.RANK.AVG(manu_pmi!I36,manu_pmi!$B36:$S36,1) -> 11 | ... S36: =_xlfn.RANK.AVG(manu_pmi!S36,manu_pmi!$B36:$S36,1) -> 2
A37: 44896 | B37: 8 | C37: 3 | D37: 9 | E37: 6 | F37: 2 | G37: 11 | H37: 7 | I37: 10 | J37: 13 | K37: 15 | L37: 4 | M37: 17 | N37: 5 | O37: 18 | P37: 15 | Q37: 15 | R37: 12 | S37: 1
A38: 44927 | B38: 5 | C38: 11 | D38: 15 | E38: 7 | F38: 10 | G38: 13 | H38: 4 | I38: 12 | J38: 18 | K38: 9 | L38: 3 | M38: 14 | N38: 6 | O38: 8 | P38: 2 | Q38: 16 | R38: 17 | S38: 1
A39: 44958 | B39: 18 | C39: 9 | D39: 11 | E39: 15 | F39: 12 | G39: 8 | H39: 5 | I39: 13 | J39: 14 | K39: 6 | L39: 2 | M39: 16 | N39: 7 | O39: 10 | P39: 1 | Q39: 4 | R39: 17 | S39: 3
A40: 44986 | B40: 8 | C40: 9 | D40: 10 | E40: 11 | F40: 16 | G40: 7 | H40: 1 | I40: 13 | J40: 17 | K40: 2 | L40: 5 | M40: 15 | N40: 4 | O40: 14 | P40: 18 | Q40: 3 | R40: 12 | S40: 6
A41: 45017 | B41: 17 | C41: 6 | D41: 9 | E41: 4 | F41: 15 | G41: 10 | H41: 1 | I41: 7 | J41: 11 | K41: 3 | L41: 12.5 | M41: 16 | N41: 5 | O41: 8 | P41: 18 | Q41: 12.5 | R41: 14 | S41: 2
A42: 45047 | B42: 3 | C42: 8 | D42: 10 | E42: 11 | F42: 15 | G42: 9 | H42: 17 | I42: 13 | J42: 14 | K42: 18 | L42: 5 | M42: 7 | N42: 12 | O42: 2 | P42: 6 | Q42: 4 | R42: 16 | S42: 1
A43: 45078 | B43: 13 | C43: 4 | D43: 7 | E43: 6 | F43: 9 | G43: 10 | H43: 13 | I43: 11 | J43: 5 | K43: 17 | L43: 8 | M43: 13 | N43: 1 | O43: 16 | P43: 18 | Q43: 3 | R43: 15 | S43: 2
A44: 45108 | B44: 1 | C44: 7 | D44: 6 | E44: 10 | F44: 13 | G44: 9 | H44: 17 | I44: 16 | J44: 12 | K44: 15 | L44: 3 | M44: 18 | N44: 2 | O44: 8 | P44: 11 | Q44: 4 | R44: 14 | S44: 5
A45: 45139 | B45: 1 | C45: 8 | D45: 9 | E45: 7 | F45: 5 | G45: 16 | H45: 2 | I45: 13 | J45: 14 | K45: 12 | L45: 10 | M45: 15 | N45: 3 | O45: 4 | P45: 18 | Q45: 6 | R45: 17 | S45: 11
A46: 45170 | B46: 12.5 | C46: 10 | D46: 7 | E46: 9 | F46: 5 | G46: 17 | H46: 2 | I46: 8 | J46: 12.5 | K46: 18 | L46: 4 | M46: 14 | N46: 3 | O46: 15 | P46: 1 | Q46: 16 | R46: 11 | S46: 6
A47: 45200 | B47: 15 | C47: 12 | D47: 7 | E47: 3 | F47: 5 | G47: 18 | H47: 8 | I47: 4 | J47: 10 | K47: 15 | L47: 9 | M47: 15 | N47: 17 | O47: 11 | P47: 1 | Q47: 2 | R47: 13 | S47: 6
A48: 45231 | B48: 5 | C48: 11 | D48: 4 | E48: 3 | F48: 12 | G48: 18 | H48: 9 | I48: 7 | J48: 10 | K48: 17 | L48: 1 | M48: 15 | N48: 14 | O48: 8 | P48: 2 | Q48: 6 | R48: 16 | S48: 13
... A71: 45931 | B71: 2 | C71: 9 | D71: 12 | E71: 8 | F71: 14 | G71: 17 | H71: 3 | I71: 10 | J71: 11 | K71: 13 | L71: 4 | M71: 7 | N71: 15 | O71: 18 | P71: 5 | Q71: 1 | R71: 16 | S71: 6

Sheet manu_rank_pct
A1: dates | B1: Apparel, Leather & Allied Products_rnk | C1: Chemical Products_rnk | D1: Computer & Electronic Products_rnk | E1: Electrical Equipment, Appliances & Components_rnk | F1: Fabricated Metal Products_rnk | G1: Food, Beverage & Tobacco Products_rnk | H1: Furniture & Related Products_rnk | I1: Machinery_rnk | J1: Miscellaneous Manufacturing_rnk | K1: Nonmetallic Mineral Products_rnk | L1: Paper Products_rnk | M1: Petroleum & Coal Products_rnk | N1: Plastics & Rubber Products_rnk | O1: Primary Metals_rnk | P1: Printing & Related Support Activities_rnk | Q1: Textile Mills_rnk | R1: Transportation Equipment_rnk | S1: Wood Products_rnk
A2: 43831 | B2: =manu_rank!B2/171 -> 0.011695906 | C2: =manu_rank!C2/171 -> 0.070175439 | D2: =manu_rank!D2/171 -> 0.087719298 | E2: =manu_rank!E2/171 -> 0.01754386 | F2: =manu_rank!F2/171 -> 0.064327485 | G2: =manu_rank!G2/171 -> 0.093567251 | H2: =manu_rank!H2/171 -> 0.10526316 | I2: =manu_rank!I2/171 -> 0.046783626 | ... S2: =manu_rank!S2/171 -> 0.099415205
A3: 43862 | B3: =manu_rank!B3/171 -> 0.023391813 | C3: =manu_rank!C3/171 -> 0.029239766 | D3: =manu_rank!D3/171 -> 0.058479532 | E3: =manu_rank!E3/171 -> 0.046783626 | F3: =manu_rank!F3/171 -> 0.040935673 | G3: =manu_rank!G3/171 -> 0.064327485 | H3: =manu_rank!H3/171 -> 0.099415205 | I3: =manu_rank!I3/171 -> 0.035087719 | ... S3: =manu_rank!S3/171 -> 0.10526316
A4: 43891 | B4: =manu_rank!B4/171 -> 0.093567251 | C4: =manu_rank!C4/171 -> 0.076023392 | D4: =manu_rank!D4/171 -> 0.070175439 | E4: =manu_rank!E4/171 -> 0.043859649 | F4: =manu_rank!F4/171 -> 0.029239766 | G4: =manu_rank!G4/171 -> 0.099415205 | H4: =manu_rank!H4/171 -> 0.023391813 | I4: =manu_rank!I4/171 -> 0.035087719 | ... S4: =manu_rank!S4/171 -> 0.087719298
A5: 43922 | B5: =manu_rank!B5/171 -> 0.093567251 | C5: =manu_rank!C5/171 -> 0.087719298 | D5: =manu_rank!D5/171 -> 0.076023392 | E5: =manu_rank!E5/171 -> 0.052631579 | F5: =manu_rank!F5/171 -> 0.029239766 | G5: =manu_rank!G5/171 -> 0.099415205 | H5: =manu_rank!H5/171 -> 0.011695906 | I5: =manu_rank!I5/171 -> 0.040935673 | ... S5: =manu_rank!S5/171 -> 0.064327485
A6: 43952 | B6: =manu_rank!B6/171 -> 0.093567251 | C6: =manu_rank!C6/171 -> 0.052631579 | D6: =manu_rank!D6/171 -> 0.058479532 | E6: =manu_rank!E6/171 -> 0.046783626 | F6: =manu_rank!F6/171 -> 0.029239766 | G6: =manu_rank!G6/171 -> 0.087719298 | H6: =manu_rank!H6/171 -> 0.099415205 | I6: =manu_rank!I6/171 -> 0.035087719 | ... S6: =manu_rank!S6/171 -> 0.076023392
A7: 43983 | B7: =manu_rank!B7/171 -> 0.081871345 | C7: =manu_rank!C7/171 -> 0.058479532 | D7: =manu_rank!D7/171 -> 0.070175439 | E7: =manu_rank!E7/171 -> 0.035087719 | F7: =manu_rank!F7/171 -> 0.01754386 | G7: =manu_rank!G7/171 -> 0.076023392 | H7: =manu_rank!H7/171 -> 0.093567251 | I7: =manu_rank!I7/171 -> 0.023391813 | ... S7: =manu_rank!S7/171 -> 0.099415205
A8: 44013 | B8: =manu_rank!B8/171 -> 0.064327485 | C8: =manu_rank!C8/171 -> 0.070175439 | D8: =manu_rank!D8/171 -> 0.058479532 | E8: =manu_rank!E8/171 -> 0.035087719 | F8: =manu_rank!F8/171 -> 0.01754386 | G8: =manu_rank!G8/171 -> 0.081871345 | H8: =manu_rank!H8/171 -> 0.099415205 | I8: =manu_rank!I8/171 -> 0.011695906 | ... S8: =manu_rank!S8/171 -> 0.10526316
A9: 44044 | B9: =manu_rank!B9/171 -> 0.052631579 | C9: =manu_rank!C9/171 -> 0.081871345 | D9: =manu_rank!D9/171 -> 0.076023392 | E9: =manu_rank!E9/171 -> 0.035087719 | F9: =manu_rank!F9/171 -> 0.064327485 | G9: =manu_rank!G9/171 -> 0.093567251 | H9: =manu_rank!H9/171 -> 0.01754386 | I9: =manu_rank!I9/171 -> 0.058479532 | ... S9: =manu_rank!S9/171 -> 0.10526316
A10: 44094 | B10: =manu_rank!B10/171 -> 0.0058479532 | C10: =manu_rank!C10/171 -> 0.064327485 | D10: =manu_rank!D10/171 -> 0.035087719 | E10: =manu_rank!E10/171 -> 0.081871345 | F10: =manu_rank!F10/171 -> 0.070175439 | G10: =manu_rank!G10/171 -> 0.093567251 | H10: =manu_rank!H10/171 -> 0.087719298 | I10: =manu_rank!I10/171 -> 0.046783626 | ... S10: =manu_rank!S10/171 -> 0.099415205
A11: 44105 | B11: =manu_rank!B11/171 -> 0.10526316 | C11: =manu_rank!C11/171 -> 0.052631579 | D11: =manu_rank!D11/171 -> 0.040935673 | E11: =manu_rank!E11/171 -> 0.029239766 | F11: =manu_rank!F11/171 -> 0.099415205 | G11: =manu_rank!G11/171 -> 0.087719298 | H11: =manu_rank!H11/171 -> 0.070175439 | I11: =manu_rank!I11/171 -> 0.076023392 | ... S11: =manu_rank!S11/171 -> 0.058479532
A12: 44136 | B12: =manu_rank!B12/171 -> 0.10526316 | C12: =manu_rank!C12/171 -> 0.058479532 | D12: =manu_rank!D12/171 -> 0.046783626 | E12: =manu_rank!E12/171 -> 0.081871345 | F12: =manu_rank!F12/171 -> 0.076023392 | G12: =manu_rank!G12/171 -> 0.01754386 | H12: =manu_rank!H12/171 -> 0.023391813 | I12: =manu_rank!I12/171 -> 0.052631579 | ... S12: =manu_rank!S12/171 -> 0.087719298
A13: 44166 | B13: =manu_rank!B13/171 -> 0.10526316 | C13: =manu_rank!C13/171 -> 0.052631579 | D13: =manu_rank!D13/171 -> 0.076023392 | E13: =manu_rank!E13/171 -> 0.029239766 | F13: =manu_rank!F13/171 -> 0.087719298 | G13: =manu_rank!G13/171 -> 0.023391813 | H13: =manu_rank!H13/171 -> 0.099415205 | I13: =manu_rank!I13/171 -> 0.081871345 | ... S13: =manu_rank!S13/171 -> 0.093567251
... A71: 45931 | B71: =manu_rank!B71/171 -> 0.011695906 | C71: =manu_rank!C71/171 -> 0.052631579 | D71: =manu_rank!D71/171 -> 0.070175439 | E71: =manu_rank!E71/171 -> 0.046783626 | F71: =manu_rank!F71/171 -> 0.081871345 | G71: =manu_rank!G71/171 -> 0.099415205 | H71: =manu_rank!H71/171 -> 0.01754386 | I71: =manu_rank!I71/171 -> 0.058479532 | ... S71: =manu_rank!S71/171 -> 0.035087719

Sheet manu_no
A1: dates | B1: Apparel, Leather & Allied Products_no | C1: Chemical Products_no | D1: Computer & Electronic Products_no | E1: Electrical Equipment, Appliances & Components_no | F1: Fabricated Metal Products_no | G1: Food, Beverage & Tobacco Products_no | H1: Furniture & Related Products_no | I1: Machinery_no | J1: Miscellaneous Manufacturing_no | K1: Nonmetallic Mineral Products_no | L1: Paper Products_no | M1: Petroleum & Coal Products_no | N1: Plastics & Rubber Products_no | O1: Primary Metals_no | P1: Printing & Related Support Activities_no | Q1: Textile Mills_no | R1: Transportation Equipment_no | S1: Wood Products_no
A2: 43831 | B2: -3 | C2: 3 | D2: 6 | E2: -2 | F2: 2 | G2: 5 | H2: 9 | I2: 1 | J2: 7 | K2: 0 | L2: 0 | M2: 0 | N2: 4 | O2: 8 | P2: -5 | Q2: -4 | R2: -1 | S2: 10
